Workbook

Sheet SUMMARY_MAX
A1: ascot 14:35 [v2.5] | N1: Ceres | O1: Chiron | P1: Eris | Q1: Juno | R1: Jupiter | S1: Ketu | T1: Mars | U1: Mercury | V1: Moon | W1: Neptune | X1: Pallas | Y1: Pluto | Z1: Rahu | AA1: Saturn | AB1: Sun | AC1: Uranus | AD1: Venus | AE1: Vesta | AF1: equator | AG1: Gonggong | AH1: Haumea | AI1: Makemake | AJ1: Orcus | AK1: Quaoar | AL1: Sedna | AM1: Transpluto | AN1: Aldebaran | AO1: Antares | AP1: Fomalhaut | AQ1: Regulus | AR1: Algol | AS1: Pleiades | AT1: Capella | AU1: Sirius | AV1: Procyon | AW1: Alkaid | AX1: Algorab | AY1: Spica | AZ1: Arcturus | BA1: Alphecca | BB1: Vega | BC1: Deneb Algedi | BD1: Rigel | BE1: Betelgeuse | BF1: Polaris | BG1: Castor | BH1: Altair | BI1: Bellatrix | BK1: Ceres | BL1: Chiron | BM1: Eris | BN1: Juno | BO1: Jupiter | BP1: Ketu | BQ1: Mars | BR1: Mercury | BS1: Moon | BT1: Neptune | BU1: Pallas | BV1: Pluto | BW1: Rahu | BX1: Saturn | BY1: Sun | BZ1: Uranus | CA1: Venus | CB1: Vesta | CC1: equator | CD1: Gonggong | CE1: Haumea | CF1: Makemake | CG1: Orcus | CH1: Quaoar | CI1: Sedna | CJ1: Transpluto | CK1: Aldebaran | CL1: Antares | CM1: Fomalhaut | CN1: Regulus | CO1: Algol | CP1: Pleiades | CQ1: Capella | CR1: Sirius | CS1: Procyon | CT1: Alkaid | CU1: Algorab | CV1: Spica | CW1: Arcturus | CX1: Alphecca | CY1: Vega | CZ1: Deneb Algedi | DA1: Rigel | DB1: Betelgeuse | DC1: Polaris | DD1: Castor | DE1: Altair | DF1: Bellatrix | DH1: Ceres | DI1: Chiron | DJ1: Eris | DK1: Juno | DL1: Jupiter | DM1: Ketu | DN1: Mars | DO1: Mercury | DP1: Moon | DQ1: Neptune | DR1: Pallas | DS1: Pluto | DT1: Rahu | DU1: Saturn | DV1: Sun | DW1: Uranus | DX1: Venus | DY1: Vesta | DZ1: equator | EA1: Gonggong | EB1: Haumea | EC1: Makemake | ED1: Orcus | EE1: Quaoar | EF1: Sedna | EG1: Transpluto | EH1: Aldebaran | EI1: Antares | EJ1: Fomalhaut | EK1: Regulus | EL1: Algol | EM1: Pleiades | EN1: Capella | EO1: Sirius | EP1: Procyon | EQ1: Alkaid | ER1: Algorab | ES1: Spica | ET1: Arcturus | EU1: Alphecca | EV1: Vega | EW1: Deneb Algedi | EX1: Rigel | EY1: Betelgeuse | EZ1: Polaris | FA1: Castor | FB1: Altair | FC1: Bellatrix | FE1: Ceres | FF1: Chiron | FG1: Eris | FH1: Juno | FI1: Jupiter | FJ1: Ketu | FK1: Mars | FL1: Mercury | FM1: Moon | FN1: Neptune | FO1: Pallas | FP1: Pluto | FQ1: Rahu | FR1: Saturn | FS1: Sun | FT1: Uranus | FU1: Venus | FV1: Vesta | FW1: equator | FX1: Gonggong | FY1: Haumea | FZ1: Makemake | GA1: Orcus | GB1: Quaoar | GC1: Sedna | GD1: Transpluto | GE1: Aldebaran | GF1: Antares | GG1: Fomalhaut | GH1: Regulus | GI1: Algol | GJ1: Pleiades | GK1: Capella | GL1: Sirius | GM1: Procyon | GN1: Alkaid | GO1: Algorab | GP1: Spica | GQ1: Arcturus | GR1: Alphecca | GS1: Vega | GT1: Deneb Algedi | GU1: Rigel | GV1: Betelgeuse | GW1: Polaris | GX1: Castor | GY1: Altair | GZ1: Bellatrix
A2: Field Max (MAX core pairs) | N2: =MAX(N7,N12) | O2: =MAX(O7,O12) | P2: =MAX(P7,P12) | Q2: =MAX(Q7,Q12) | R2: =MAX(R7,R12) | S2: =MAX(S7,S12) | T2: =MAX(T7,T12) | U2: =MAX(U7,U12) | ... BI2: =MAX(BI7,BI12) | BK2: =MAX(BK7,BK12) | BL2: =MAX(BL7,BL12) | BM2: =MAX(BM7,BM12) | BN2: =MAX(BN7,BN12) | BO2: =MAX(BO7,BO12) | BP2: =MAX(BP7,BP12) | BQ2: =MAX(BQ7,BQ12) | BR2: =MAX(BR7,BR12) | ... DF2: =MAX(DF7,DF12) | DH2: =MAX(DH7,DH12) | DI2: =MAX(DI7,DI12) | DJ2: =MAX(DJ7,DJ12) | DK2: =MAX(DK7,DK12) | DL2: =MAX(DL7,DL12) | DM2: =MAX(DM7,DM12) | DN2: =MAX(DN7,DN12) | DO2: =MAX(DO7,DO12) | ... FC2: =MAX(FC7,FC12) | FE2: =MAX(FE7,FE12) | FF2: =MAX(FF7,FF12) | FG2: =MAX(FG7,FG12) | FH2: =MAX(FH7,FH12) | FI2: =MAX(FI7,FI12) | FJ2: =MAX(FJ7,FJ12) | FK2: =MAX(FK7,FK12) | FL2: =MAX(FL7,FL12) | ... GZ2: =MAX(GZ7,GZ12)
A3: Gap (1st to 2nd) | N3: =LARGE((N7,N12),1)-LARGE((N7,N12),2) | O3: =LARGE((O7,O12),1)-LARGE((O7,O12),2) | P3: =LARGE((P7,P12),1)-LARGE((P7,P12),2) | Q3: =LARGE((Q7,Q12),1)-LARGE((Q7,Q12),2) | R3: =LARGE((R7,R12),1)-LARGE((R7,R12),2) | S3: =LARGE((S7,S12),1)-LARGE((S7,S12),2) | T3: =LARGE((T7,T12),1)-LARGE((T7,T12),2) | U3: =LARGE((U7,U12),1)-LARGE((U7,U12),2) | ... BI3: =LARGE((BI7,BI12),1)-LARGE((BI7,BI12),2) | BK3: =LARGE((BK7,BK12),1)-LARGE((BK7,BK12),2) | BL3: =LARGE((BL7,BL12),1)-LARGE((BL7,BL12),2) | BM3: =LARGE((BM7,BM12),1)-LARGE((BM7,BM12),2) | BN3: =LARGE((BN7,BN12),1)-LARGE((BN7,BN12),2) | BO3: =LARGE((BO7,BO12),1)-LARGE((BO7,BO12),2) | BP3: =LARGE((BP7,BP12),1)-LARGE((BP7,BP12),2) | BQ3: =LARGE((BQ7,BQ12),1)-LARGE((BQ7,BQ12),2) | BR3: =LARGE((BR7,BR12),1)-LARGE((BR7,BR12),2) | ... DF3: =LARGE((DF7,DF12),1)-LARGE((DF7,DF12),2) | DH3: =LARGE((DH7,DH12),1)-LARGE((DH7,DH12),2) | DI3: =LARGE((DI7,DI12),1)-LARGE((DI7,DI12),2) | DJ3: =LARGE((DJ7,DJ12),1)-LARGE((DJ7,DJ12),2) | DK3: =LARGE((DK7,DK12),1)-LARGE((DK7,DK12),2) | DL3: =LARGE((DL7,DL12),1)-LARGE((DL7,DL12),2) | DM3: =LARGE((DM7,DM12),1)-LARGE((DM7,DM12),2) | DN3: =LARGE((DN7,DN12),1)-LARGE((DN7,DN12),2) | DO3: =LARGE((DO7,DO12),1)-LARGE((DO7,DO12),2) | ... FC3: =LARGE((FC7,FC12),1)-LARGE((FC7,FC12),2) | FE3: =LARGE((FE7,FE12),1)-LARGE((FE7,FE12),2) | FF3: =LARGE((FF7,FF12),1)-LARGE((FF7,FF12),2) | FG3: =LARGE((FG7,FG12),1)-LARGE((FG7,FG12),2) | FH3: =LARGE((FH7,FH12),1)-LARGE((FH7,FH12),2) | FI3: =LARGE((FI7,FI12),1)-LARGE((FI7,FI12),2) | FJ3: =LARGE((FJ7,FJ12),1)-LARGE((FJ7,FJ12),2) | FK3: =LARGE((FK7,FK12),1)-LARGE((FK7,FK12),2) | FL3: =LARGE((FL7,FL12),1)-LARGE((FL7,FL12),2) | ... GZ3: =LARGE((GZ7,GZ12),1)-LARGE((GZ7,GZ12),2)
A4: Diffident | N4: TYPE 1 - MAX | BK4: TYPE 2 - MAX | DH4: TYPE 1 - MAX + TT | FE4: TYPE 2 - MAX + TT
A5: Margin (to leader / 2nd) | N5: =IF(N7=0,"",IF(N7=N2,N7-LARGE((N7,N12),2),N7-N2)) | O5: =IF(O7=0,"",IF(O7=O2,O7-LARGE((O7,O12),2),O7-O2)) | P5: =IF(P7=0,"",IF(P7=P2,P7-LARGE((P7,P12),2),P7-P2)) | Q5: =IF(Q7=0,"",IF(Q7=Q2,Q7-LARGE((Q7,Q12),2),Q7-Q2)) | R5: =IF(R7=0,"",IF(R7=R2,R7-LARGE((R7,R12),2),R7-R2)) | S5: =IF(S7=0,"",IF(S7=S2,S7-LARGE((S7,S12),2),S7-S2)) | T5: =IF(T7=0,"",IF(T7=T2,T7-LARGE((T7,T12),2),T7-T2)) | U5: =IF(U7=0,"",IF(U7=U2,U7-LARGE((U7,U12),2),U7-U2)) | ... BI5: =IF(BI7=0,"",IF(BI7=BI2,BI7-LARGE((BI7,BI12),2),BI7-BI2)) | BK5: =IF(BK7=0,"",IF(BK7=BK2,BK7-LARGE((BK7,BK12),2),BK7-BK2)) | BL5: =IF(BL7=0,"",IF(BL7=BL2,BL7-LARGE((BL7,BL12),2),BL7-BL2)) | BM5: =IF(BM7=0,"",IF(BM7=BM2,BM7-LARGE((BM7,BM12),2),BM7-BM2)) | BN5: =IF(BN7=0,"",IF(BN7=BN2,BN7-LARGE((BN7,BN12),2),BN7-BN2)) | BO5: =IF(BO7=0,"",IF(BO7=BO2,BO7-LARGE((BO7,BO12),2),BO7-BO2)) | BP5: =IF(BP7=0,"",IF(BP7=BP2,BP7-LARGE((BP7,BP12),2),BP7-BP2)) | BQ5: =IF(BQ7=0,"",IF(BQ7=BQ2,BQ7-LARGE((BQ7,BQ12),2),BQ7-BQ2)) | BR5: =IF(BR7=0,"",IF(BR7=BR2,BR7-LARGE((BR7,BR12),2),BR7-BR2)) | ... DF5: =IF(DF7=0,"",IF(DF7=DF2,DF7-LARGE((DF7,DF12),2),DF7-DF2)) | DH5: =IF(DH7=0,"",IF(DH7=DH2,DH7-LARGE((DH7,DH12),2),DH7-DH2)) | DI5: =IF(DI7=0,"",IF(DI7=DI2,DI7-LARGE((DI7,DI12),2),DI7-DI2)) | DJ5: =IF(DJ7=0,"",IF(DJ7=DJ2,DJ7-LARGE((DJ7,DJ12),2),DJ7-DJ2)) | DK5: =IF(DK7=0,"",IF(DK7=DK2,DK7-LARGE((DK7,DK12),2),DK7-DK2)) | DL5: =IF(DL7=0,"",IF(DL7=DL2,DL7-LARGE((DL7,DL12),2),DL7-DL2)) | DM5: =IF(DM7=0,"",IF(DM7=DM2,DM7-LARGE((DM7,DM12),2),DM7-DM2)) | DN5: =IF(DN7=0,"",IF(DN7=DN2,DN7-LARGE((DN7,DN12),2),DN7-DN2)) | DO5: =IF(DO7=0,"",IF(DO7=DO2,DO7-LARGE((DO7,DO12),2),DO7-DO2)) | ... FC5: =IF(FC7=0,"",IF(FC7=FC2,FC7-LARGE((FC7,FC12),2),FC7-FC2)) | FE5: =IF(FE7=0,"",IF(FE7=FE2,FE7-LARGE((FE7,FE12),2),FE7-FE2)) | FF5: =IF(FF7=0,"",IF(FF7=FF2,FF7-LARGE((FF7,FF12),2),FF7-FF2)) | FG5: =IF(FG7=0,"",IF(FG7=FG2,FG7-LARGE((FG7,FG12),2),FG7-FG2)) | FH5: =IF(FH7=0,"",IF(FH7=FH2,FH7-LARGE((FH7,FH12),2),FH7-FH2)) | FI5: =IF(FI7=0,"",IF(FI7=FI2,FI7-LARGE((FI7,FI12),2),FI7-FI2)) | FJ5: =IF(FJ7=0,"",IF(FJ7=FJ2,FJ7-LARGE((FJ7,FJ12),2),FJ7-FJ2)) | FK5: =IF(FK7=0,"",IF(FK7=FK2,FK7-LARGE((FK7,FK12),2),FK7-FK2)) | FL5: =IF(FL7=0,"",IF(FL7=FL2,FL7-LARGE((FL7,FL12),2),FL7-FL2)) | ... GZ5: =IF(GZ7=0,"",IF(GZ7=GZ2,GZ7-LARGE((GZ7,GZ12),2),GZ7-GZ2))
A6: Rank | N6: =IF(N7=0,"",1+(N7>N7)+(N12>N7)) | O6: =IF(O7=0,"",1+(O7>O7)+(O12>O7)) | P6: =IF(P7=0,"",1+(P7>P7)+(P12>P7)) | Q6: =IF(Q7=0,"",1+(Q7>Q7)+(Q12>Q7)) | R6: =IF(R7=0,"",1+(R7>R7)+(R12>R7)) | S6: =IF(S7=0,"",1+(S7>S7)+(S12>S7)) | T6: =IF(T7=0,"",1+(T7>T7)+(T12>T7)) | U6: =IF(U7=0,"",1+(U7>U7)+(U12>U7)) | ... BI6: =IF(BI7=0,"",1+(BI7>BI7)+(BI12>BI7)) | BK6: =IF(BK7=0,"",1+(BK7>BK7)+(BK12>BK7)) | BL6: =IF(BL7=0,"",1+(BL7>BL7)+(BL12>BL7)) | BM6: =IF(BM7=0,"",1+(BM7>BM7)+(BM12>BM7)) | BN6: =IF(BN7=0,"",1+(BN7>BN7)+(BN12>BN7)) | BO6: =IF(BO7=0,"",1+(BO7>BO7)+(BO12>BO7)) | BP6: =IF(BP7=0,"",1+(BP7>BP7)+(BP12>BP7)) | BQ6: =IF(BQ7=0,"",1+(BQ7>BQ7)+(BQ12>BQ7)) | BR6: =IF(BR7=0,"",1+(BR7>BR7)+(BR12>BR7)) | ... DF6: =IF(DF7=0,"",1+(DF7>DF7)+(DF12>DF7)) | DH6: =IF(DH7=0,"",1+(DH7>DH7)+(DH12>DH7)) | DI6: =IF(DI7=0,"",1+(DI7>DI7)+(DI12>DI7)) | DJ6: =IF(DJ7=0,"",1+(DJ7>DJ7)+(DJ12>DJ7)) | DK6: =IF(DK7=0,"",1+(DK7>DK7)+(DK12>DK7)) | DL6: =IF(DL7=0,"",1+(DL7>DL7)+(DL12>DL7)) | DM6: =IF(DM7=0,"",1+(DM7>DM7)+(DM12>DM7)) | DN6: =IF(DN7=0,"",1+(DN7>DN7)+(DN12>DN7)) | DO6: =IF(DO7=0,"",1+(DO7>DO7)+(DO12>DO7)) | ... FC6: =IF(FC7=0,"",1+(FC7>FC7)+(FC12>FC7)) | FE6: =IF(FE7=0,"",1+(FE7>FE7)+(FE12>FE7)) | FF6: =IF(FF7=0,"",1+(FF7>FF7)+(FF12>FF7)) | FG6: =IF(FG7=0,"",1+(FG7>FG7)+(FG12>FG7)) | FH6: =IF(FH7=0,"",1+(FH7>FH7)+(FH12>FH7)) | FI6: =IF(FI7=0,"",1+(FI7>FI7)+(FI12>FI7)) | FJ6: =IF(FJ7=0,"",1+(FJ7>FJ7)+(FJ12>FJ7)) | FK6: =IF(FK7=0,"",1+(FK7>FK7)+(FK12>FK7)) | FL6: =IF(FL7=0,"",1+(FL7>FL7)+(FL12>FL7)) | ... GZ6: =IF(GZ7=0,"",1+(GZ7>GZ7)+(GZ12>GZ7))
A7: MAX (core pairs) | N7: ='P01'!N7 | O7: ='P01'!O7 | P7: ='P01'!P7 | Q7: ='P01'!Q7 | R7: ='P01'!R7 | S7: ='P01'!S7 | T7: ='P01'!T7 | U7: ='P01'!U7 | ... BI7: ='P01'!BI7 | BK7: ='P01'!BK7 | BL7: ='P01'!BL7 | BM7: ='P01'!BM7 | BN7: ='P01'!BN7 | BO7: ='P01'!BO7 | BP7: ='P01'!BP7 | BQ7: ='P01'!BQ7 | BR7: ='P01'!BR7 | ... DF7: ='P01'!DF7 | DH7: ='P01'!DH7 | DI7: ='P01'!DI7 | DJ7: ='P01'!DJ7 | DK7: ='P01'!DK7 | DL7: ='P01'!DL7 | DM7: ='P01'!DM7 | DN7: ='P01'!DN7 | DO7: ='P01'!DO7 | ... FC7: ='P01'!FC7 | FE7: ='P01'!FE7 | FF7: ='P01'!FF7 | FG7: ='P01'!FG7 | FH7: ='P01'!FH7 | FI7: ='P01'!FI7 | FJ7: ='P01'!FJ7 | FK7: ='P01'!FK7 | FL7: ='P01'!FL7 | ... GZ7: ='P01'!GZ7
A9: Frankie Dettori | N9: TYPE 1 - MAX | BK9: TYPE 2 - MAX | DH9: TYPE 1 - MAX + TT | FE9: TYPE 2 - MAX + TT
A10: Margin (to leader / 2nd) | N10: =IF(N12=0,"",IF(N12=N2,N12-LARGE((N7,N12),2),N12-N2)) | O10: =IF(O12=0,"",IF(O12=O2,O12-LARGE((O7,O12),2),O12-O2)) | P10: =IF(P12=0,"",IF(P12=P2,P12-LARGE((P7,P12),2),P12-P2)) | Q10: =IF(Q12=0,"",IF(Q12=Q2,Q12-LARGE((Q7,Q12),2),Q12-Q2)) | R10: =IF(R12=0,"",IF(R12=R2,R12-LARGE((R7,R12),2),R12-R2)) | S10: =IF(S12=0,"",IF(S12=S2,S12-LARGE((S7,S12),2),S12-S2)) | T10: =IF(T12=0,"",IF(T12=T2,T12-LARGE((T7,T12),2),T12-T2)) | U10: =IF(U12=0,"",IF(U12=U2,U12-LARGE((U7,U12),2),U12-U2)) | ... BI10: =IF(BI12=0,"",IF(BI12=BI2,BI12-LARGE((BI7,BI12),2),BI12-BI2)) | BK10: =IF(BK12=0,"",IF(BK12=BK2,BK12-LARGE((BK7,BK12),2),BK12-BK2)) | BL10: =IF(BL12=0,"",IF(BL12=BL2,BL12-LARGE((BL7,BL12),2),BL12-BL2)) | BM10: =IF(BM12=0,"",IF(BM12=BM2,BM12-LARGE((BM7,BM12),2),BM12-BM2)) | BN10: =IF(BN12=0,"",IF(BN12=BN2,BN12-LARGE((BN7,BN12),2),BN12-BN2)) | BO10: =IF(BO12=0,"",IF(BO12=BO2,BO12-LARGE((BO7,BO12),2),BO12-BO2)) | BP10: =IF(BP12=0,"",IF(BP12=BP2,BP12-LARGE((BP7,BP12),2),BP12-BP2)) | BQ10: =IF(BQ12=0,"",IF(BQ12=BQ2,BQ12-LARGE((BQ7,BQ12),2),BQ12-BQ2)) | BR10: =IF(BR12=0,"",IF(BR12=BR2,BR12-LARGE((BR7,BR12),2),BR12-BR2)) | ... DF10: =IF(DF12=0,"",IF(DF12=DF2,DF12-LARGE((DF7,DF12),2),DF12-DF2)) | DH10: =IF(DH12=0,"",IF(DH12=DH2,DH12-LARGE((DH7,DH12),2),DH12-DH2)) | DI10: =IF(DI12=0,"",IF(DI12=DI2,DI12-LARGE((DI7,DI12),2),DI12-DI2)) | DJ10: =IF(DJ12=0,"",IF(DJ12=DJ2,DJ12-LARGE((DJ7,DJ12),2),DJ12-DJ2)) | DK10: =IF(DK12=0,"",IF(DK12=DK2,DK12-LARGE((DK7,DK12),2),DK12-DK2)) | DL10: =IF(DL12=0,"",IF(DL12=DL2,DL12-LARGE((DL7,DL12),2),DL12-DL2)) | DM10: =IF(DM12=0,"",IF(DM12=DM2,DM12-LARGE((DM7,DM12),2),DM12-DM2)) | DN10: =IF(DN12=0,"",IF(DN12=DN2,DN12-LARGE((DN7,DN12),2),DN12-DN2)) | DO10: =IF(DO12=0,"",IF(DO12=DO2,DO12-LARGE((DO7,DO12),2),DO12-DO2)) | ... FC10: =IF(FC12=0,"",IF(FC12=FC2,FC12-LARGE((FC7,FC12),2),FC12-FC2)) | FE10: =IF(FE12=0,"",IF(FE12=FE2,FE12-LARGE((FE7,FE12),2),FE12-FE2)) | FF10: =IF(FF12=0,"",IF(FF12=FF2,FF12-LARGE((FF7,FF12),2),FF12-FF2)) | FG10: =IF(FG12=0,"",IF(FG12=FG2,FG12-LARGE((FG7,FG12),2),FG12-FG2)) | FH10: =IF(FH12=0,"",IF(FH12=FH2,FH12-LARGE((FH7,FH12),2),FH12-FH2)) | FI10: =IF(FI12=0,"",IF(FI12=FI2,FI12-LARGE((FI7,FI12),2),FI12-FI2)) | FJ10: =IF(FJ12=0,"",IF(FJ12=FJ2,FJ12-LARGE((FJ7,FJ12),2),FJ12-FJ2)) | FK10: =IF(FK12=0,"",IF(FK12=FK2,FK12-LARGE((FK7,FK12),2),FK12-FK2)) | FL10: =IF(FL12=0,"",IF(FL12=FL2,FL12-LARGE((FL7,FL12),2),FL12-FL2)) | ... GZ10: =IF(GZ12=0,"",IF(GZ12=GZ2,GZ12-LARGE((GZ7,GZ12),2),GZ12-GZ2))
A11: Rank | N11: =IF(N12=0,"",1+(N7>N12)+(N12>N12)) | O11: =IF(O12=0,"",1+(O7>O12)+(O12>O12)) | P11: =IF(P12=0,"",1+(P7>P12)+(P12>P12)) | Q11: =IF(Q12=0,"",1+(Q7>Q12)+(Q12>Q12)) | R11: =IF(R12=0,"",1+(R7>R12)+(R12>R12)) | S11: =IF(S12=0,"",1+(S7>S12)+(S12>S12)) | T11: =IF(T12=0,"",1+(T7>T12)+(T12>T12)) | U11: =IF(U12=0,"",1+(U7>U12)+(U12>U12)) | ... BI11: =IF(BI12=0,"",1+(BI7>BI12)+(BI12>BI12)) | BK11: =IF(BK12=0,"",1+(BK7>BK12)+(BK12>BK12)) | BL11: =IF(BL12=0,"",1+(BL7>BL12)+(BL12>BL12)) | BM11: =IF(BM12=0,"",1+(BM7>BM12)+(BM12>BM12)) | BN11: =IF(BN12=0,"",1+(BN7>BN12)+(BN12>BN12)) | BO11: =IF(BO12=0,"",1+(BO7>BO12)+(BO12>BO12)) | BP11: =IF(BP12=0,"",1+(BP7>BP12)+(BP12>BP12)) | BQ11: =IF(BQ12=0,"",1+(BQ7>BQ12)+(BQ12>BQ12)) | BR11: =IF(BR12=0,"",1+(BR7>BR12)+(BR12>BR12)) | ... DF11: =IF(DF12=0,"",1+(DF7>DF12)+(DF12>DF12)) | DH11: =IF(DH12=0,"",1+(DH7>DH12)+(DH12>DH12)) | DI11: =IF(DI12=0,"",1+(DI7>DI12)+(DI12>DI12)) | DJ11: =IF(DJ12=0,"",1+(DJ7>DJ12)+(DJ12>DJ12)) | DK11: =IF(DK12=0,"",1+(DK7>DK12)+(DK12>DK12)) | DL11: =IF(DL12=0,"",1+(DL7>DL12)+(DL12>DL12)) | DM11: =IF(DM12=0,"",1+(DM7>DM12)+(DM12>DM12)) | DN11: =IF(DN12=0,"",1+(DN7>DN12)+(DN12>DN12)) | DO11: =IF(DO12=0,"",1+(DO7>DO12)+(DO12>DO12)) | ... FC11: =IF(FC12=0,"",1+(FC7>FC12)+(FC12>FC12)) | FE11: =IF(FE12=0,"",1+(FE7>FE12)+(FE12>FE12)) | FF11: =IF(FF12=0,"",1+(FF7>FF12)+(FF12>FF12)) | FG11: =IF(FG12=0,"",1+(FG7>FG12)+(FG12>FG12)) | FH11: =IF(FH12=0,"",1+(FH7>FH12)+(FH12>FH12)) | FI11: =IF(FI12=0,"",1+(FI7>FI12)+(FI12>FI12)) | FJ11: =IF(FJ12=0,"",1+(FJ7>FJ12)+(FJ12>FJ12)) | FK11: =IF(FK12=0,"",1+(FK7>FK12)+(FK12>FK12)) | FL11: =IF(FL12=0,"",1+(FL7>FL12)+(FL12>FL12)) | ... GZ11: =IF(GZ12=0,"",1+(GZ7>GZ12)+(GZ12>GZ12))
A12: MAX (core pairs) | N12: ='P02'!N7 | O12: ='P02'!O7 | P12: ='P02'!P7 | Q12: ='P02'!Q7 | R12: ='P02'!R7 | S12: ='P02'!S7 | T12: ='P02'!T7 | U12: ='P02'!U7 | ... BI12: ='P02'!BI7 | BK12: ='P02'!BK7 | BL12: ='P02'!BL7 | BM12: ='P02'!BM7 | BN12: ='P02'!BN7 | BO12: ='P02'!BO7 | BP12: ='P02'!BP7 | BQ12: ='P02'!BQ7 | BR12: ='P02'!BR7 | ... DF12: ='P02'!DF7 | DH12: ='P02'!DH7 | DI12: ='P02'!DI7 | DJ12: ='P02'!DJ7 | DK12: ='P02'!DK7 | DL12: ='P02'!DL7 | DM12: ='P02'!DM7 | DN12: ='P02'!DN7 | DO12: ='P02'!DO7 | ... FC12: ='P02'!FC7 | FE12: ='P02'!FE7 | FF12: ='P02'!FF7 | FG12: ='P02'!FG7 | FH12: ='P02'!FH7 | FI12: ='P02'!FI7 | FJ12: ='P02'!FJ7 | FK12: ='P02'!FK7 | FL12: ='P02'!FL7 | ... GZ12: ='P02'!GZ7

Sheet SUMMARY
A1: ascot 14:35 [v2.5] | N1: Ceres | O1: Chiron | P1: Eris | Q1: Juno | R1: Jupiter | S1: Ketu | T1: Mars | U1: Mercury | V1: Moon | W1: Neptune | X1: Pallas | Y1: Pluto | Z1: Rahu | AA1: Saturn | AB1: Sun | AC1: Uranus | AD1: Venus | AE1: Vesta | AF1: equator | AG1: Gonggong | AH1: Haumea | AI1: Makemake | AJ1: Orcus | AK1: Quaoar | AL1: Sedna | AM1: Transpluto | AN1: Aldebaran | AO1: Antares | AP1: Fomalhaut | AQ1: Regulus | AR1: Algol | AS1: Pleiades | AT1: Capella | AU1: Sirius | AV1: Procyon | AW1: Alkaid | AX1: Algorab | AY1: Spica | AZ1: Arcturus | BA1: Alphecca | BB1: Vega | BC1: Deneb Algedi | BD1: Rigel | BE1: Betelgeuse | BF1: Polaris | BG1: Castor | BH1: Altair | BI1: Bellatrix | BK1: Ceres | BL1: Chiron | BM1: Eris | BN1: Juno | BO1: Jupiter | BP1: Ketu | BQ1: Mars | BR1: Mercury | BS1: Moon | BT1: Neptune | BU1: Pallas | BV1: Pluto | BW1: Rahu | BX1: Saturn | BY1: Sun | BZ1: Uranus | CA1: Venus | CB1: Vesta | CC1: equator | CD1: Gonggong | CE1: Haumea | CF1: Makemake | CG1: Orcus | CH1: Quaoar | CI1: Sedna | CJ1: Transpluto | CK1: Aldebaran | CL1: Antares | CM1: Fomalhaut | CN1: Regulus | CO1: Algol | CP1: Pleiades | CQ1: Capella | CR1: Sirius | CS1: Procyon | CT1: Alkaid | CU1: Algorab | CV1: Spica | CW1: Arcturus | CX1: Alphecca | CY1: Vega | CZ1: Deneb Algedi | DA1: Rigel | DB1: Betelgeuse | DC1: Polaris | DD1: Castor | DE1: Altair | DF1: Bellatrix | DH1: Ceres | DI1: Chiron | DJ1: Eris | DK1: Juno | DL1: Jupiter | DM1: Ketu | DN1: Mars | DO1: Mercury | DP1: Moon | DQ1: Neptune | DR1: Pallas | DS1: Pluto | DT1: Rahu | DU1: Saturn | DV1: Sun | DW1: Uranus | DX1: Venus | DY1: Vesta | DZ1: equator | EA1: Gonggong | EB1: Haumea | EC1: Makemake | ED1: Orcus | EE1: Quaoar | EF1: Sedna | EG1: Transpluto | EH1: Aldebaran | EI1: Antares | EJ1: Fomalhaut | EK1: Regulus | EL1: Algol | EM1: Pleiades | EN1: Capella | EO1: Sirius | EP1: Procyon | EQ1: Alkaid | ER1: Algorab | ES1: Spica | ET1: Arcturus | EU1: Alphecca | EV1: Vega | EW1: Deneb Algedi | EX1: Rigel | EY1: Betelgeuse | EZ1: Polaris | FA1: Castor | FB1: Altair | FC1: Bellatrix | FE1: Ceres | FF1: Chiron | FG1: Eris | FH1: Juno | FI1: Jupiter | FJ1: Ketu | FK1: Mars | FL1: Mercury | FM1: Moon | FN1: Neptune | FO1: Pallas | FP1: Pluto | FQ1: Rahu | FR1: Saturn | FS1: Sun | FT1: Uranus | FU1: Venus | FV1: Vesta | FW1: equator | FX1: Gonggong | FY1: Haumea | FZ1: Makemake | GA1: Orcus | GB1: Quaoar | GC1: Sedna | GD1: Transpluto | GE1: Aldebaran | GF1: Antares | GG1: Fomalhaut | GH1: Regulus | GI1: Algol | GJ1: Pleiades | GK1: Capella | GL1: Sirius | GM1: Procyon | GN1: Alkaid | GO1: Algorab | GP1: Spica | GQ1: Arcturus | GR1: Alphecca | GS1: Vega | GT1: Deneb Algedi | GU1: Rigel | GV1: Betelgeuse | GW1: Polaris | GX1: Castor | GY1: Altair | GZ1: Bellatrix
A2: Field Max (MAIN SUMMARY) | N2: 39.61 | O2: 734.77 | P2: 70.86 | Q2: 265.94 | R2: 305.76 | S2: 188.94 | T2: 533.26 | U2: 111.49 | V2: 70.44 | W2: 411.5 | X2: 213.68 | Z2: 139.29 | AA2: 329.22 | AB2: 1019.29 | AC2: 202.21 | AD2: 103.14 | AE2: 421.12 | AH2: 123.08 | AJ2: 256.96 | AL2: 434.86 | AO2: 172.69 | AP2: 136.11 | AQ2: 150.99 | AT2: 338.07 | AU2: 549.21 | AV2: 392.86 | AW2: 276.88 | AY2: 149.11 | AZ2: 365.18 | BA2: 84.99 | BB2: 153.05 | BC2: 163.85 | BD2: 248.71 | BE2: 250.63 | BF2: 233.8 | BH2: 221.21 | BI2: 179.84 | BK2: 297.6 | BL2: 148.83 | BM2: 373.69 | BN2: 716.88 | BO2: 377.91 | BP2: 295.32 | BQ2: 265.93 | BR2: 277.91 | BS2: 201.98 | BT2: 459.56 | BU2: 649.1 | BV2: 101.88 | BW2: 678.04 | BX2: 797.79 | BY2: 600.23 | BZ2: 280.09 | CA2: 992.04 | CB2: 523.31 | CD2: 307.4 | CE2: 641.23 | CG2: 624.16 | CH2: 639.29 | CI2: 391.95 | CJ2: 316.9 | CK2: 364.67 | CL2: 54.08 | CM2: 213.86 | CN2: 145.17 | CO2: 303.66 | CQ2: 224.87 | CR2: 75.2 | CS2: 197.53 | CT2: 182.66 | CV2: 901.74 | CW2: 127.75 | CX2: 587.93 | CY2: 198.09 | CZ2: 671.43 | DA2: 106.61 | DB2: 452.78 | DE2: 378.8 | DF2: 287.29 | DH2: 39.61 | DI2: 870.04 | DJ2: 70.86 | DK2: 361.45 | DL2: 305.76 | DM2: 188.94 | DN2: 533.26 | DO2: 111.49 | DP2: 70.44 | DQ2: 411.5 | DR2: 213.68 | DT2: 139.29 | DU2: 411.85 | DV2: 1154.24 | DW2: 202.21 | DX2: 183.18 | DY2: 509.85 | EB2: 123.08 | ED2: 256.96 | EF2: 583.36 | EI2: 268.24 | EJ2: 269.7 | EK2: 239.36 | EN2: 524.26 | EO2: 1038.14 | EP2: 614.92 | EQ2: 478.81 | ES2: 237.41 | ET2: 591.73 | EU2: 180.82 | EV2: 320.64 | EW2: 245.06 | EX2: 343.46 | EY2: 540.99 | EZ2: 327.68 | FB2: 341.73 | FC2: 274.05 | FE2: 297.6 | FF2: 234.93 | FG2: 373.69 | FH2: 919.03 | FI2: 377.91 | FJ2: 324.02 | FK2: 436.97 | FL2: 361.74 | FM2: 204.93 | FN2: 553.77 | FO2: 1068.92 | FP2: 298.08 | FQ2: 706.75 | FR2: 895.89 | FS2: 761.4 | FT2: 551.24 | FU2: 1507.73 | FV2: 604.17 | FX2: 360.85 | FY2: 726.58 | GA2: 1021.32 | GB2: 1081.85 | GC2: 590.59 | GD2: 412.42 | GE2: 364.67 | GF2: 54.08 | GG2: 409.47 | GH2: 145.17 | GI2: 536.44 | GK2: 273.21 | GL2: 123.54 | GM2: 290.07 | GN2: 195.45 | GP2: 1067.95 | GQ2: 211.57 | GR2: 636.27 | GS2: 336.31 | GT2: 950.55 | GU2: 171.99 | GV2: 692.49 | GY2: 407.51 | GZ2: 542.43
A3: Gap (1st to 2nd) | O3: 636.29 | Q3: 61.24 | R3: 55.18 | S3: 143.54 | W3: 259.09 | X3: 95.17 | AA3: 255.52 | AB3: 725.34 | AC3: 86.88 | AD3: 57.02 | AE3: 295.54 | AJ3: 128.18 | AL3: 290.75 | AQ3: 66.09 | AT3: 154.94 | AU3: 238.69 | AV3: 122.96 | AW3: 178.4 | AY3: 62.91 | BA3: 7.41 | BB3: 9.08 | BD3: 99.82 | BE3: 38.4 | BH3: 86.29 | BL3: 91.09 | BN3: 402.73 | BP3: 223.51 | BQ3: 171.51 | BS3: 33.07 | BT3: 385.03 | BU3: 344.09 | BW3: 410.07 | BY3: 301.7 | BZ3: 168.63 | CB3: 175.41 | CD3: 144.81 | CE3: 539.38 | CG3: 224.39 | CI3: 76.24 | CJ3: 142.63 | CM3: 127.39 | CN3: 21.96 | CQ3: 48.73 | CR3: 6.86 | CS3: 169.22 | CV3: 549.57 | CX3: 473.03 | CY3: 1.04 | DA3: 29.37 | DB3: 173.79 | DE3: 271.74 | DI3: 731.63 | DK3: 156.75 | DL3: 55.18 | DM3: 143.54 | DQ3: 259.09 | DR3: 0.96 | DU3: 338.15 | DV3: 860.29 | DW3: 86.88 | DX3: 137.06 | DY3: 384.27 | ED3: 128.18 | EF3: 439.25 | EK3: 66.1 | EN3: 254.56 | EO3: 407.53 | EP3: 126.59 | EQ3: 285.85 | ES3: 64.79 | EU3: 7.41 | EV3: 9.09 | EX3: 99.82 | EY3: 132.6 | FB3: 126.65 | FF3: 137.26 | FH3: 437.23 | FJ3: 152.21 | FK3: 342.55 | FM3: 36.02 | FN3: 462.85 | FO3: 574.41 | FQ3: 158.26 | FS3: 446.48 | FT3: 391.44 | FV3: 158.17 | FX3: 5.09 | FY3: 576.39 | GA3: 621.55 | GC3: 167.44 | GD3: 61.87 | GG3: 123 | GH3: 21.96 | GK3: 48.72 | GL3: 6.86 | GM3: 261.76 | GP3: 634.92 | GR3: 473.03 | GS3: 1.05 | GU3: 65.38 | GV3: 359.25 | GY3: 300.45
A4: Diffident | N4: TYPE 1 - MAIN | BK4: TYPE 2 - MAIN | DH4: TYPE 1 - MAIN + TT | FE4: TYPE 2 - MAIN + TT
A5: Margin (to leader / 2nd) | O5: 636.29 | Q5: 61.24 | R5: 55.18 | S5: 143.54 | W5: 259.09 | X5: -95.17 | AA5: -255.52 | AB5: -725.34 | AC5: -86.88 | AD5: 57.02 | AE5: -295.54 | AJ5: 128.18 | AL5: -290.75 | AQ5: -66.09 | AT5: 154.94 | AU5: -238.69 | AV5: 122.96 | AW5: 178.4 | AY5: 62.91 | BA5: -7.41 | BB5: -9.08 | BD5: 99.82 | BE5: 38.4 | BH5: 86.29 | BL5: -91.09 | BN5: -402.73 | BP5: 223.51 | BQ5: -171.51 | BS5: 33.07 | BT5: 385.03 | BU5: -344.09 | BW5: 410.07 | BY5: 301.7 | BZ5: 168.63 | CB5: 175.41 | CD5: -144.81 | CE5: 539.38 | CG5: 224.39 | CI5: -76.24 | CJ5: 142.63 | CM5: -127.39 | CN5: 21.96 | CQ5: 48.73 | CR5: 6.86 | CS5: 169.22 | CV5: 549.57 | CX5: -473.03 | CY5: -1.04 | DA5: -29.37 | DB5: -173.79 | DE5: 271.74 | DI5: 731.63 | DK5: 156.75 | DL5: 55.18 | DM5: 143.54 | DQ5: 259.09 | DR5: -0.96 | DU5: -338.15 | DV5: -860.29 | DW5: -86.88 | DX5: 137.06 | DY5: -384.27 | ED5: 128.18 | EF5: -439.25 | EK5: -66.1 | EN5: 254.56 | EO5: -407.53 | EP5: 126.59 | EQ5: 285.85 | ES5: 64.79 | EU5: -7.41 | EV5: -9.09 | EX5: 99.82 | EY5: 132.6 | FB5: 126.65 | FF5: -137.26 | FH5: -437.23 | FJ5: 152.21 | FK5: -342.55 | FM5: 36.02 | FN5: 462.85 | FO5: -574.41 | FQ5: 158.26 | FS5: 446.48 | FT5: 391.44 | FV5: 158.17 | FX5: 5.09 | FY5: 576.39 | GA5: 621.55 | GC5: -167.44 | GD5: 61.87 | GG5: -123 | GH5: 21.96 | GK5: 48.72 | GL5: 6.86 | GM5: 261.76 | GP5: 634.92 | GR5: -473.03 | GS5: -1.05 | GU5: 65.38 | GV5: -359.25 | GY5: 300.45
A6: Rank | N6: 1 | O6: 1 | P6: 1 | Q6: 1 | R6: 1 | S6: 1 | T6: 1 | V6: 1 | W6: 1 | X6: 2 | Z6: 1 | AA6: 2 | AB6: 2 | AC6: 2 | AD6: 1 | AE6: 2 | AH6: 1 | AJ6: 1 | AL6: 2 | AQ6: 2 | AT6: 1 | AU6: 2 | AV6: 1 | AW6: 1 | AY6: 1 | AZ6: 1 | BA6: 2 | BB6: 2 | BC6: 1 | BD6: 1 | BE6: 1 | BF6: 1 | BH6: 1 | BI6: 1 | BK6: 1 | BL6: 2 | BM6: 1 | BN6: 2 | BO6: 1 | BP6: 1 | BQ6: 2 | BR6: 1 | BS6: 1 | BT6: 1 | BU6: 2 | BW6: 1 | BY6: 1 | BZ6: 1 | CB6: 1 | CD6: 2 | CE6: 1 | CG6: 1 | CI6: 2 | CJ6: 1 | CK6: 1 | CM6: 2 | CN6: 1 | CQ6: 1 | CR6: 1 | CS6: 1 | CT6: 1 | CV6: 1 | CW6: 1 | CX6: 2 | CY6: 2 | CZ6: 1 | DA6: 2 | DB6: 2 | DE6: 1 | DF6: 1 | DH6: 1 | DI6: 1 | DJ6: 1 | DK6: 1 | DL6: 1 | DM6: 1 | DN6: 1 | DP6: 1 | DQ6: 1 | DR6: 2 | DT6: 1 | DU6: 2 | DV6: 2 | DW6: 2 | DX6: 1 | DY6: 2 | EB6: 1 | ED6: 1 | EF6: 2 | EK6: 2 | EN6: 1 | EO6: 2 | EP6: 1 | EQ6: 1 | ES6: 1 | ET6: 1 | EU6: 2 | EV6: 2 | EW6: 1 | EX6: 1 | EY6: 1 | EZ6: 1 | FB6: 1 | FC6: 1 | FE6: 1 | FF6: 2 | FG6: 1 | FH6: 2 | FI6: 1 | FJ6: 1 | FK6: 2 | FL6: 1 | FM6: 1 | FN6: 1 | FO6: 2 | FQ6: 1 | FS6: 1 | FT6: 1 | FV6: 1 | FX6: 1 | FY6: 1 | GA6: 1 | GC6: 2 | GD6: 1 | GE6: 1 | GG6: 2 | GH6: 1 | GK6: 1 | GL6: 1 | GM6: 1 | GN6: 1 | GP6: 1 | GQ6: 1 | GR6: 2 | GS6: 2 | GT6: 1 | GU6: 1 | GV6: 2 | GY6: 1 | GZ6: 1
A7: Total (MAIN SUMMARY only) | N7: ='P01'!N86 | O7: ='P01'!O86 | P7: ='P01'!P86 | Q7: ='P01'!Q86 | R7: ='P01'!R86 | S7: ='P01'!S86 | T7: ='P01'!T86 | U7: ='P01'!U86 | ... BI7: ='P01'!BI86 | BK7: ='P01'!BK86 | BL7: ='P01'!BL86 | BM7: ='P01'!BM86 | BN7: ='P01'!BN86 | BO7: ='P01'!BO86 | BP7: ='P01'!BP86 | BQ7: ='P01'!BQ86 | BR7: ='P01'!BR86 | ... DF7: ='P01'!DF86 | DH7: ='P01'!DH86 | DI7: ='P01'!DI86 | DJ7: ='P01'!DJ86 | DK7: ='P01'!DK86 | DL7: ='P01'!DL86 | DM7: ='P01'!DM86 | DN7: ='P01'!DN86 | DO7: ='P01'!DO86 | ... FC7: ='P01'!FC86 | FE7: ='P01'!FE86 | FF7: ='P01'!FF86 | FG7: ='P01'!FG86 | FH7: ='P01'!FH86 | FI7: ='P01'!FI86 | FJ7: ='P01'!FJ86 | FK7: ='P01'!FK86 | FL7: ='P01'!FL86 | ... GZ7: ='P01'!GZ86
A9: Frankie Dettori | N9: TYPE 1 - MAIN | BK9: TYPE 2 - MAIN | DH9: TYPE 1 - MAIN + TT | FE9: TYPE 2 - MAIN + TT
A10: Margin (to leader / 2nd) | O10: -636.29 | Q10: -61.24 | R10: -55.18 | S10: -143.54 | W10: -259.09 | X10: 95.17 | AA10: 255.52 | AB10: 725.34 | AC10: 86.88 | AD10: -57.02 | AE10: 295.54 | AJ10: -128.18 | AL10: 290.75 | AQ10: 66.09 | AT10: -154.94 | AU10: 238.69 | AV10: -122.96 | AW10: -178.4 | AY10: -62.91 | BA10: 7.41 | BB10: 9.08 | BD10: -99.82 | BE10: -38.4 | BH10: -86.29 | BL10: 91.09 | BN10: 402.73 | BP10: -223.51 | BQ10: 171.51 | BS10: -33.07 | BT10: -385.03 | BU10: 344.09 | BW10: -410.07 | BY10: -301.7 | BZ10: -168.63 | CB10: -175.41 | CD10: 144.81 | CE10: -539.38 | CG10: -224.39 | CI10: 76.24 | CJ10: -142.63 | CM10: 127.39 | CN10: -21.96 | CQ10: -48.73 | CR10: -6.86 | CS10: -169.22 | CV10: -549.57 | CX10: 473.03 | CY10: 1.04 | DA10: 29.37 | DB10: 173.79 | DE10: -271.74 | DI10: -731.63 | DK10: -156.75 | DL10: -55.18 | DM10: -143.54 | DQ10: -259.09 | DR10: 0.96 | DU10: 338.15 | DV10: 860.29 | DW10: 86.88 | DX10: -137.06 | DY10: 384.27 | ED10: -128.18 | EF10: 439.25 | EK10: 66.1 | EN10: -254.56 | EO10: 407.53 | EP10: -126.59 | EQ10: -285.85 | ES10: -64.79 | EU10: 7.41 | EV10: 9.09 | EX10: -99.82 | EY10: -132.6 | FB10: -126.65 | FF10: 137.26 | FH10: 437.23 | FJ10: -152.21 | FK10: 342.55 | FM10: -36.02 | FN10: -462.85 | FO10: 574.41 | FQ10: -158.26 | FS10: -446.48 | FT10: -391.44 | FV10: -158.17 | FX10: -5.09 | FY10: -576.39 | GA10: -621.55 | GC10: 167.44 | GD10: -61.87 | GG10: 123 | GH10: -21.96 | GK10: -48.72 | GL10: -6.86 | GM10: -261.76 | GP10: -634.92 | GR10: 473.03 | GS10: 1.05 | GU10: -65.38 | GV10: 359.25 | GY10: -300.45
A11: Rank | O11: 2 | Q11: 2 | R11: 2 | S11: 2 | U11: 1 | W11: 2 | X11: 1 | AA11: 1 | AB11: 1 | AC11: 1 | AD11: 2 | AE11: 1 | AJ11: 2 | AL11: 1 | AO11: 1 | AP11: 1 | AQ11: 1 | AT11: 2 | AU11: 1 | AV11: 2 | AW11: 2 | AY11: 2 | BA11: 1 | BB11: 1 | BD11: 2 | BE11: 2 | BH11: 2 | BL11: 1 | BN11: 1 | BP11: 2 | BQ11: 1 | BS11: 2 | BT11: 2 | BU11: 1 | BV11: 1 | BW11: 2 | BX11: 1 | BY11: 2 | BZ11: 2 | CA11: 1 | CB11: 2 | CD11: 1 | CE11: 2 | CG11: 2 | CH11: 1 | CI11: 1 | CJ11: 2 | CL11: 1 | CM11: 1 | CN11: 2 | CO11: 1 | CQ11: 2 | CR11: 2 | CS11: 2 | CV11: 2 | CX11: 1 | CY11: 1 | DA11: 1 | DB11: 1 | DE11: 2 | DI11: 2 | DK11: 2 | DL11: 2 | DM11: 2 | DO11: 1 | DQ11: 2 | DR11: 1 | DU11: 1 | DV11: 1 | DW11: 1 | DX11: 2 | DY11: 1 | ED11: 2 | EF11: 1 | EI11: 1 | EJ11: 1 | EK11: 1 | EN11: 2 | EO11: 1 | EP11: 2 | EQ11: 2 | ES11: 2 | EU11: 1 | EV11: 1 | EX11: 2 | EY11: 2 | FB11: 2 | FF11: 1 | FH11: 1 | FJ11: 2 | FK11: 1 | FM11: 2 | FN11: 2 | FO11: 1 | FP11: 1 | FQ11: 2 | FR11: 1 | FS11: 2 | FT11: 2 | FU11: 1 | FV11: 2 | FX11: 2 | FY11: 2 | GA11: 2 | GB11: 1 | GC11: 1 | GD11: 2 | GF11: 1 | GG11: 1 | GH11: 2 | GI11: 1 | GK11: 2 | GL11: 2 | GM11: 2 | GP11: 2 | GR11: 1 | GS11: 1 | GU11: 2 | GV11: 1 | GY11: 2
A12: Total (MAIN SUMMARY only) | N12: ='P02'!N86 | O12: ='P02'!O86 | P12: ='P02'!P86 | Q12: ='P02'!Q86 | R12: ='P02'!R86 | S12: ='P02'!S86 | T12: ='P02'!T86 | U12: ='P02'!U86 | ... BI12: ='P02'!BI86 | BK12: ='P02'!BK86 | BL12: ='P02'!BL86 | BM12: ='P02'!BM86 | BN12: ='P02'!BN86 | BO12: ='P02'!BO86 | BP12: ='P02'!BP86 | BQ12: ='P02'!BQ86 | BR12: ='P02'!BR86 | ... DF12: ='P02'!DF86 | DH12: ='P02'!DH86 | DI12: ='P02'!DI86 | DJ12: ='P02'!DJ86 | DK12: ='P02'!DK86 | DL12: ='P02'!DL86 | DM12: ='P02'!DM86 | DN12: ='P02'!DN86 | DO12: ='P02'!DO86 | ... FC12: ='P02'!FC86 | FE12: ='P02'!FE86 | FF12: ='P02'!FF86 | FG12: ='P02'!FG86 | FH12: ='P02'!FH86 | FI12: ='P02'!FI86 | FJ12: ='P02'!FJ86 | FK12: ='P02'!FK86 | FL12: ='P02'!FL86 | ... GZ12: ='P02'!GZ86

Sheet P01
A1: Diffident | N1: SELF / DIRECT / CROSS HITS BY BODY | BK1: MATCH HITS BY BODY | DH1: SELF / DIRECT / CROSS (+ transit pair vibration score) | FE1: MATCH (+ transit pair vibration score)
A2: ascot 14:35 [v2.5] | N2: Ceres | O2: Chiron | P2: Eris | Q2: Juno | R2: Jupiter | S2: Ketu | T2: Mars | U2: Mercury | V2: Moon | W2: Neptune | X2: Pallas | Y2: Pluto | Z2: Rahu | AA2: Saturn | AB2: Sun | AC2: Uranus | AD2: Venus | AE2: Vesta | AF2: equator | AG2: Gonggong | AH2: Haumea | AI2: Makemake | AJ2: Orcus | AK2: Quaoar | AL2: Sedna | AM2: Transpluto | AN2: Aldebaran | AO2: Antares | AP2: Fomalhaut | AQ2: Regulus | AR2: Algol | AS2: Pleiades | AT2: Capella | AU2: Sirius | AV2: Procyon | AW2: Alkaid | AX2: Algorab | AY2: Spica | AZ2: Arcturus | BA2: Alphecca | BB2: Vega | BC2: Deneb Algedi | BD2: Rigel | BE2: Betelgeuse | BF2: Polaris | BG2: Castor | BH2: Altair | BI2: Bellatrix | BK2: Ceres | BL2: Chiron | BM2: Eris | BN2: Juno | BO2: Jupiter | BP2: Ketu | BQ2: Mars | BR2: Mercury | BS2: Moon | BT2: Neptune | BU2: Pallas | BV2: Pluto | BW2: Rahu | BX2: Saturn | BY2: Sun | BZ2: Uranus | CA2: Venus | CB2: Vesta | CC2: equator | CD2: Gonggong | CE2: Haumea | CF2: Makemake | CG2: Orcus | CH2: Quaoar | CI2: Sedna | CJ2: Transpluto | CK2: Aldebaran | CL2: Antares | CM2: Fomalhaut | CN2: Regulus | CO2: Algol | CP2: Pleiades | CQ2: Capella | CR2: Sirius | CS2: Procyon | CT2: Alkaid | CU2: Algorab | CV2: Spica | CW2: Arcturus | CX2: Alphecca | CY2: Vega | CZ2: Deneb Algedi | DA2: Rigel | DB2: Betelgeuse | DC2: Polaris | DD2: Castor | DE2: Altair | DF2: Bellatrix | DH2: Ceres | DI2: Chiron | DJ2: Eris | DK2: Juno | DL2: Jupiter | DM2: Ketu | DN2: Mars | DO2: Mercury | DP2: Moon | DQ2: Neptune | DR2: Pallas | DS2: Pluto | DT2: Rahu | DU2: Saturn | DV2: Sun | DW2: Uranus | DX2: Venus | DY2: Vesta | DZ2: equator | EA2: Gonggong | EB2: Haumea | EC2: Makemake | ED2: Orcus | EE2: Quaoar | EF2: Sedna | EG2: Transpluto | EH2: Aldebaran | EI2: Antares | EJ2: Fomalhaut | EK2: Regulus | EL2: Algol | EM2: Pleiades | EN2: Capella | EO2: Sirius | EP2: Procyon | EQ2: Alkaid | ER2: Algorab | ES2: Spica | ET2: Arcturus | EU2: Alphecca | EV2: Vega | EW2: Deneb Algedi | EX2: Rigel | EY2: Betelgeuse | EZ2: Polaris | FA2: Castor | FB2: Altair | FC2: Bellatrix | FE2: Ceres | FF2: Chiron | FG2: Eris | FH2: Juno | FI2: Jupiter | FJ2: Ketu | FK2: Mars | FL2: Mercury | FM2: Moon | FN2: Neptune | FO2: Pallas | FP2: Pluto | FQ2: Rahu | FR2: Saturn | FS2: Sun | FT2: Uranus | FU2: Venus | FV2: Vesta | FW2: equator | FX2: Gonggong | FY2: Haumea | FZ2: Makemake | GA2: Orcus | GB2: Quaoar | GC2: Sedna | GD2: Transpluto | GE2: Aldebaran | GF2: Antares | GG2: Fomalhaut | GH2: Regulus | GI2: Algol | GJ2: Pleiades | GK2: Capella | GL2: Sirius | GM2: Procyon | GN2: Alkaid | GO2: Algorab | GP2: Spica | GQ2: Arcturus | GR2: Alphecca | GS2: Vega | GT2: Deneb Algedi | GU2: Rigel | GV2: Betelgeuse | GW2: Polaris | GX2: Castor | GY2: Altair | GZ2: Bellatrix
O3: 625.27 | P3: 97.13 | Q3: 157.15 | R3: 133.75 | S3: 70.89 | T3: 754.3 | U3: 10.37 | V3: 125.26 | W3: 82.83 | X3: 88.01 | Z3: 114.35 | AA3: 40.77 | AB3: 100.4 | AC3: 173.73 | AD3: 165.53 | AE3: 74.52 | AG3: 44.84 | AH3: 176.96 | AI3: 26.87 | AJ3: 106.77 | AL3: 82.47 | AN3: 88.71 | AO3: 97.14 | AP3: 186.27 | AQ3: 84.9 | AT3: 338.08 | AU3: 395.83 | AV3: 616.61 | AW3: 276.89 | AY3: 447.55 | AZ3: 365.17 | BA3: 77.58 | BB3: 238.38 | BC3: 352.58 | BD3: 248.71 | BE3: 327.16 | BF3: 246 | BG3: 119.25 | BH3: 333.11 | BI3: 179.84 | BK3: 134.56 | BM3: 155.84 | BN3: 264.19 | BO3: 81.56 | BP3: 60.27 | BQ3: 275.79 | BR3: 113.13 | BS3: 207.97 | BT3: 188.37 | BU3: 299.9 | BW3: 283.26 | BX3: 132.39 | BY3: 140.56 | BZ3: 265.91 | CA3: 63.88 | CB3: 493.06 | CD3: 227.56 | CE3: 371.89 | CF3: 30.73 | CG3: 403.04 | CH3: 17.89 | CI3: 310.29 | CJ3: 273.61 | CK3: 181.94 | CL3: 57.95 | CM3: 67.05 | CN3: 82.32 | CO3: 4.44 | CP3: 12.8 | CQ3: 69.87 | CR3: 75.2 | CS3: 70.66 | CT3: 7.37 | CU3: 30.67 | CV3: 550.77 | CX3: 114.9 | CY3: 111.31 | CZ3: 198.07 | DB3: 153.88 | DE3: 87.16 | DF3: 204.12 | DI3: 760.53 | DJ3: 97.13 | DK3: 157.15 | DL3: 133.75 | DM3: 70.89 | DN3: 762.35 | DO3: 10.37 | DP3: 219 | DQ3: 82.83 | DR3: 88.01 | DT3: 228.71 | DU3: 40.77 | DV3: 100.4 | DW3: 173.73 | DX3: 245.56 | DY3: 74.52 | EA3: 44.84 | EB3: 176.96 | EC3: 26.87 | ED3: 106.77 | EF3: 82.47 | EH3: 177.92 | EI3: 192.69 | EJ3: 400.78 | EK3: 173.26 | EN3: 524.26 | EO3: 796.03 | EP3: 1062.42 | EQ3: 478.81 | ES3: 881.74 | ET3: 591.72 | EU3: 173.41 | EV3: 501.23 | EW3: 630.35 | EX3: 343.46 | EY3: 711.47 | EZ3: 339.88 | FA3: 214.23 | FB3: 533.8 | FC3: 274.05 | FE3: 134.56 | FG3: 155.84 | FH3: 613.85 | FI3: 81.56 | FJ3: 259.96 | FK3: 303.28 | FL3: 113.13 | FM3: 207.97 | FN3: 456.9 | FO3: 460.82 | FQ3: 283.26 | FR3: 318.79 | FS3: 169.27 | FT3: 454.33 | FU3: 260.07 | FV3: 675.68 | FX3: 425.82 | FY3: 554.51 | FZ3: 30.73 | GA3: 897.28 | GB3: 17.89 | GC3: 617.73 | GD3: 273.61 | GE3: 181.94 | GF3: 106.3 | GG3: 267.05 | GH3: 150.99 | GI3: 392.37 | GJ3: 12.8 | GK3: 118.21 | GL3: 123.54 | GM3: 70.66 | GN3: 7.37 | GO3: 37.75 | GP3: 733.39 | GR3: 163.24 | GS3: 159.66 | GT3: 841.67 | GV3: 383.14 | GY3: 115.87 | GZ3: 389.29
A5: QUALIFYING CORE PAIRS (score >= 80)
A6: Pair | B6: RA Score | C6: Dec Score | D6: RA Dist | E6: Dec Dist
A7: MAX | N7: =MAX(N8:N62) | O7: =MAX(O8:O62) | P7: =MAX(P8:P62) | Q7: =MAX(Q8:Q62) | R7: =MAX(R8:R62) | S7: =MAX(S8:S62) | T7: =MAX(T8:T62) | U7: =MAX(U8:U62) | ... BI7: =MAX(BI8:BI62) | BK7: =MAX(BK8:BK62) | BL7: =MAX(BL8:BL62) | BM7: =MAX(BM8:BM62) | BN7: =MAX(BN8:BN62) | BO7: =MAX(BO8:BO62) | BP7: =MAX(BP8:BP62) | BQ7: =MAX(BQ8:BQ62) | BR7: =MAX(BR8:BR62) | ... DF7: =MAX(DF8:DF62) | DH7: =MAX(DH8:DH62) | DI7: =MAX(DI8:DI62) | DJ7: =MAX(DJ8:DJ62) | DK7: =MAX(DK8:DK62) | DL7: =MAX(DL8:DL62) | DM7: =MAX(DM8:DM62) | DN7: =MAX(DN8:DN62) | DO7: =MAX(DO8:DO62) | ... FC7: =MAX(FC8:FC62) | FE7: =MAX(FE8:FE62) | FF7: =MAX(FF8:FF62) | FG7: =MAX(FG8:FG62) | FH7: =MAX(FH8:FH62) | FI7: =MAX(FI8:FI62) | FJ7: =MAX(FJ8:FJ62) | FK7: =MAX(FK8:FK62) | FL7: =MAX(FL8:FL62) | ... GZ7: =MAX(GZ8:GZ62)
A8: Ketu / Rahu | B8: 100 | D8: 180 | E8: 6.390653 | N8: =SUM(N88:N118) | O8: =SUM(O88:O118) | P8: =SUM(P88:P118) | Q8: =SUM(Q88:Q118) | R8: =SUM(R88:R118) | S8: =SUM(S88:S118) | T8: =SUM(T88:T118) | U8: =SUM(U88:U118) | ... BI8: =SUM(BI88:BI118) | BK8: =SUM(BK88:BK118) | BL8: =SUM(BL88:BL118) | BM8: =SUM(BM88:BM118) | BN8: =SUM(BN88:BN118) | BO8: =SUM(BO88:BO118) | BP8: =SUM(BP88:BP118) | BQ8: =SUM(BQ88:BQ118) | BR8: =SUM(BR88:BR118) | ... DF8: =SUM(DF88:DF118) | DH8: =SUM(DH88:DH118) | DI8: =SUM(DI88:DI118) | DJ8: =SUM(DJ88:DJ118) | DK8: =SUM(DK88:DK118) | DL8: =SUM(DL88:DL118) | DM8: =SUM(DM88:DM118) | DN8: =SUM(DN88:DN118) | DO8: =SUM(DO88:DO118) | ... FC8: =SUM(FC88:FC118) | FE8: =SUM(FE88:FE118) | FF8: =SUM(FF88:FF118) | FG8: =SUM(FG88:FG118) | FH8: =SUM(FH88:FH118) | FI8: =SUM(FI88:FI118) | FJ8: =SUM(FJ88:FJ118) | FK8: =SUM(FK88:FK118) | FL8: =SUM(FL88:FL118) | ... GZ8: =SUM(GZ88:GZ118)
A9: Ketu / Vesta | B9: 3.54 | C9: 99.63 | D9: 118.77098 | E9: 24.142358 | N9: =SUM(N125:N149) | O9: =SUM(O125:O149) | P9: =SUM(P125:P149) | Q9: =SUM(Q125:Q149) | R9: =SUM(R125:R149) | S9: =SUM(S125:S149) | T9: =SUM(T125:T149) | U9: =SUM(U125:U149) | ... BI9: =SUM(BI125:BI149) | BK9: =SUM(BK125:BK149) | BL9: =SUM(BL125:BL149) | BM9: =SUM(BM125:BM149) | BN9: =SUM(BN125:BN149) | BO9: =SUM(BO125:BO149) | BP9: =SUM(BP125:BP149) | BQ9: =SUM(BQ125:BQ149) | BR9: =SUM(BR125:BR149) | ... DF9: =SUM(DF125:DF149) | DH9: =SUM(DH125:DH149) | DI9: =SUM(DI125:DI149) | DJ9: =SUM(DJ125:DJ149) | DK9: =SUM(DK125:DK149) | DL9: =SUM(DL125:DL149) | DM9: =SUM(DM125:DM149) | DN9: =SUM(DN125:DN149) | DO9: =SUM(DO125:DO149) | ... FC9: =SUM(FC125:FC149) | FE9: =SUM(FE125:FE149) | FF9: =SUM(FF125:FF149) | FG9: =SUM(FG125:FG149) | FH9: =SUM(FH125:FH149) | FI9: =SUM(FI125:FI149) | FJ9: =SUM(FJ125:FJ149) | FK9: =SUM(FK125:FK149) | FL9: =SUM(FL125:FL149) | ... GZ9: =SUM(GZ125:GZ149)
A10: Neptune / Capella | C10: 99.61 | D10: 142.27988 | E10: 66.667118 | N10: =SUM(N151:N170) | O10: =SUM(O151:O170) | P10: =SUM(P151:P170) | Q10: =SUM(Q151:Q170) | R10: =SUM(R151:R170) | S10: =SUM(S151:S170) | T10: =SUM(T151:T170) | U10: =SUM(U151:U170) | ... BI10: =SUM(BI151:BI170) | BK10: =SUM(BK151:BK170) | BL10: =SUM(BL151:BL170) | BM10: =SUM(BM151:BM170) | BN10: =SUM(BN151:BN170) | BO10: =SUM(BO151:BO170) | BP10: =SUM(BP151:BP170) | BQ10: =SUM(BQ151:BQ170) | BR10: =SUM(BR151:BR170) | ... DF10: =SUM(DF151:DF170) | DH10: =SUM(DH151:DH170) | DI10: =SUM(DI151:DI170) | DJ10: =SUM(DJ151:DJ170) | DK10: =SUM(DK151:DK170) | DL10: =SUM(DL151:DL170) | DM10: =SUM(DM151:DM170) | DN10: =SUM(DN151:DN170) | DO10: =SUM(DO151:DO170) | ... FC10: =SUM(FC151:FC170) | FE10: =SUM(FE151:FE170) | FF10: =SUM(FF151:FF170) | FG10: =SUM(FG151:FG170) | FH10: =SUM(FH151:FH170) | FI10: =SUM(FI151:FI170) | FJ10: =SUM(FJ151:FJ170) | FK10: =SUM(FK151:FK170) | FL10: =SUM(FL151:FL170) | ... GZ10: =SUM(GZ151:GZ170)
A11: Chiron / Sun | B11: 99.13 | D11: 11.11058 | E11: 5.828722 | N11: =SUM(N172:N206) | O11: =SUM(O172:O206) | P11: =SUM(P172:P206) | Q11: =SUM(Q172:Q206) | R11: =SUM(R172:R206) | S11: =SUM(S172:S206) | T11: =SUM(T172:T206) | U11: =SUM(U172:U206) | ... BI11: =SUM(BI172:BI206) | BK11: =SUM(BK172:BK206) | BL11: =SUM(BL172:BL206) | BM11: =SUM(BM172:BM206) | BN11: =SUM(BN172:BN206) | BO11: =SUM(BO172:BO206) | BP11: =SUM(BP172:BP206) | BQ11: =SUM(BQ172:BQ206) | BR11: =SUM(BR172:BR206) | ... DF11: =SUM(DF172:DF206) | DH11: =SUM(DH172:DH206) | DI11: =SUM(DI172:DI206) | DJ11: =SUM(DJ172:DJ206) | DK11: =SUM(DK172:DK206) | DL11: =SUM(DL172:DL206) | DM11: =SUM(DM172:DM206) | DN11: =SUM(DN172:DN206) | DO11: =SUM(DO172:DO206) | ... FC11: =SUM(FC172:FC206) | FE11: =SUM(FE172:FE206) | FF11: =SUM(FF172:FF206) | FG11: =SUM(FG172:FG206) | FH11: =SUM(FH172:FH206) | FI11: =SUM(FI172:FI206) | FJ11: =SUM(FJ172:FJ206) | FK11: =SUM(FK172:FK206) | FL11: =SUM(FL172:FL206) | ... GZ11: =SUM(GZ172:GZ206)
A12: Saturn / Vesta | B12: 98.1 | D12: 115.96524 | E12: 20.083771 | N12: =SUM(N208:N223) | O12: =SUM(O208:O223) | P12: =SUM(P208:P223) | Q12: =SUM(Q208:Q223) | R12: =SUM(R208:R223) | S12: =SUM(S208:S223) | T12: =SUM(T208:T223) | U12: =SUM(U208:U223) | ... BI12: =SUM(BI208:BI223) | BK12: =SUM(BK208:BK223) | BL12: =SUM(BL208:BL223) | BM12: =SUM(BM208:BM223) | BN12: =SUM(BN208:BN223) | BO12: =SUM(BO208:BO223) | BP12: =SUM(BP208:BP223) | BQ12: =SUM(BQ208:BQ223) | BR12: =SUM(BR208:BR223) | ... DF12: =SUM(DF208:DF223) | DH12: =SUM(DH208:DH223) | DI12: =SUM(DI208:DI223) | DJ12: =SUM(DJ208:DJ223) | DK12: =SUM(DK208:DK223) | DL12: =SUM(DL208:DL223) | DM12: =SUM(DM208:DM223) | DN12: =SUM(DN208:DN223) | DO12: =SUM(DO208:DO223) | ... FC12: =SUM(FC208:FC223) | FE12: =SUM(FE208:FE223) | FF12: =SUM(FF208:FF223) | FG12: =SUM(FG208:FG223) | FH12: =SUM(FH208:FH223) | FI12: =SUM(FI208:FI223) | FJ12: =SUM(FJ208:FJ223) | FK12: =SUM(FK208:FK223) | FL12: =SUM(FL208:FL223) | ... GZ12: =SUM(GZ208:GZ223)
A13: Eris / Haumea | C13: 97.87 | D13: 169.95967 | E13: 29.124959 | N13: =SUM(N247:N264) | O13: =SUM(O247:O264) | P13: =SUM(P247:P264) | Q13: =SUM(Q247:Q264) | R13: =SUM(R247:R264) | S13: =SUM(S247:S264) | T13: =SUM(T247:T264) | U13: =SUM(U247:U264) | ... BI13: =SUM(BI247:BI264) | BK13: =SUM(BK247:BK264) | BL13: =SUM(BL247:BL264) | BM13: =SUM(BM247:BM264) | BN13: =SUM(BN247:BN264) | BO13: =SUM(BO247:BO264) | BP13: =SUM(BP247:BP264) | BQ13: =SUM(BQ247:BQ264) | BR13: =SUM(BR247:BR264) | ... DF13: =SUM(DF247:DF264) | DH13: =SUM(DH247:DH264) | DI13: =SUM(DI247:DI264) | DJ13: =SUM(DJ247:DJ264) | DK13: =SUM(DK247:DK264) | DL13: =SUM(DL247:DL264) | DM13: =SUM(DM247:DM264) | DN13: =SUM(DN247:DN264) | DO13: =SUM(DO247:DO264) | ... FC13: =SUM(FC247:FC264) | FE13: =SUM(FE247:FE264) | FF13: =SUM(FF247:FF264) | FG13: =SUM(FG247:FG264) | FH13: =SUM(FH247:FH264) | FI13: =SUM(FI247:FI264) | FJ13: =SUM(FJ247:FJ264) | FK13: =SUM(FK247:FK264) | FL13: =SUM(FL247:FL264) | ... GZ13: =SUM(GZ247:GZ264)
A14: Pallas / Fomalhaut | B14: 97.81 | D14: 111.12451 | E14: 38.904994 | N14: =SUM(N266:N272) | O14: =SUM(O266:O272) | P14: =SUM(P266:P272) | Q14: =SUM(Q266:Q272) | R14: =SUM(R266:R272) | S14: =SUM(S266:S272) | T14: =SUM(T266:T272) | U14: =SUM(U266:U272) | ... BI14: =SUM(BI266:BI272) | BK14: =SUM(BK266:BK272) | BL14: =SUM(BL266:BL272) | BM14: =SUM(BM266:BM272) | BN14: =SUM(BN266:BN272) | BO14: =SUM(BO266:BO272) | BP14: =SUM(BP266:BP272) | BQ14: =SUM(BQ266:BQ272) | BR14: =SUM(BR266:BR272) | ... DF14: =SUM(DF266:DF272) | DH14: =SUM(DH266:DH272) | DI14: =SUM(DI266:DI272) | DJ14: =SUM(DJ266:DJ272) | DK14: =SUM(DK266:DK272) | DL14: =SUM(DL266:DL272) | DM14: =SUM(DM266:DM272) | DN14: =SUM(DN266:DN272) | DO14: =SUM(DO266:DO272) | ... FC14: =SUM(FC266:FC272) | FE14: =SUM(FE266:FE272) | FF14: =SUM(FF266:FF272) | FG14: =SUM(FG266:FG272) | FH14: =SUM(FH266:FH272) | FI14: =SUM(FI266:FI272) | FJ14: =SUM(FJ266:FJ272) | FK14: =SUM(FK266:FK272) | FL14: =SUM(FL266:FL272) | ... GZ14: =SUM(GZ266:GZ272)
A15: Moon / Venus | B15: 96.37 | C15: 93.74 | D15: 122.19603 | E15: 6.181323 | N15: 0 | O15: 0 | P15: 0 | Q15: 0 | R15: 0 | S15: 0 | T15: 0 | U15: 0 | V15: 0 | W15: 0 | X15: 0 | Y15: 0 | Z15: 0 | AA15: 0 | AB15: 0 | AC15: 0 | AD15: 0 | AE15: 0 | AF15: 0 | AG15: 0 | AH15: 0 | AI15: 0 | AJ15: 0 | AK15: 0 | AL15: 0 | AM15: 0 | AN15: 0 | AO15: 0 | AP15: 0 | AQ15: 0 | AR15: 0 | AS15: 0 | AT15: 0 | AU15: 0 | AV15: 0 | AW15: 0 | AX15: 0 | AY15: 0 | AZ15: 0 | BA15: 0 | BB15: 0 | BC15: 0 | BD15: 0 | BE15: 0 | BF15: 0 | BG15: 0 | BH15: 0 | BI15: 0 | BK15: 0 | BL15: 0 | BM15: 0 | BN15: 0 | BO15: 0 | BP15: 0 | BQ15: 0 | BR15: 0 | BS15: 0 | BT15: 0 | BU15: 0 | BV15: 0 | BW15: 0 | BX15: 0 | BY15: 0 | BZ15: 0 | CA15: 0 | CB15: 0 | CC15: 0 | CD15: 0 | CE15: 0 | CF15: 0 | CG15: 0 | CH15: 0 | CI15: 0 | CJ15: 0 | CK15: 0 | CL15: 0 | CM15: 0 | CN15: 0 | CO15: 0 | CP15: 0 | CQ15: 0 | CR15: 0 | CS15: 0 | CT15: 0 | CU15: 0 | CV15: 0 | CW15: 0 | CX15: 0 | CY15: 0 | CZ15: 0 | DA15: 0 | DB15: 0 | DC15: 0 | DD15: 0 | DE15: 0 | DF15: 0 | DH15: 0 | DI15: 0 | DJ15: 0 | DK15: 0 | DL15: 0 | DM15: 0 | DN15: 0 | DO15: 0 | DP15: 0 | DQ15: 0 | DR15: 0 | DS15: 0 | DT15: 0 | DU15: 0 | DV15: 0 | DW15: 0 | DX15: 0 | DY15: 0 | DZ15: 0 | EA15: 0 | EB15: 0 | EC15: 0 | ED15: 0 | EE15: 0 | EF15: 0 | EG15: 0 | EH15: 0 | EI15: 0 | EJ15: 0 | EK15: 0 | EL15: 0 | EM15: 0 | EN15: 0 | EO15: 0 | EP15: 0 | EQ15: 0 | ER15: 0 | ES15: 0 | ET15: 0 | EU15: 0 | EV15: 0 | EW15: 0 | EX15: 0 | EY15: 0 | EZ15: 0 | FA15: 0 | FB15: 0 | FC15: 0 | FE15: 0 | FF15: 0 | FG15: 0 | FH15: 0 | FI15: 0 | FJ15: 0 | FK15: 0 | FL15: 0 | FM15: 0 | FN15: 0 | FO15: 0 | FP15: 0 | FQ15: 0 | FR15: 0 | FS15: 0 | FT15: 0 | FU15: 0 | FV15: 0 | FW15: 0 | FX15: 0 | FY15: 0 | FZ15: 0 | GA15: 0 | GB15: 0 | GC15: 0 | GD15: 0 | GE15: 0 | GF15: 0 | GG15: 0 | GH15: 0 | GI15: 0 | GJ15: 0 | GK15: 0 | GL15: 0 | GM15: 0 | GN15: 0 | GO15: 0 | GP15: 0 | GQ15: 0 | GR15: 0 | GS15: 0 | GT15: 0 | GU15: 0 | GV15: 0 | GW15: 0 | GX15: 0 | GY15: 0 | GZ15: 0
A16: Neptune / Polaris | B16: 96.22 | D16: 101.39789 | E16: 109.93542 | N16: =SUM(N279:N285) | O16: =SUM(O279:O285) | P16: =SUM(P279:P285) | Q16: =SUM(Q279:Q285) | R16: =SUM(R279:R285) | S16: =SUM(S279:S285) | T16: =SUM(T279:T285) | U16: =SUM(U279:U285) | ... BI16: =SUM(BI279:BI285) | BK16: =SUM(BK279:BK285) | BL16: =SUM(BL279:BL285) | BM16: =SUM(BM279:BM285) | BN16: =SUM(BN279:BN285) | BO16: =SUM(BO279:BO285) | BP16: =SUM(BP279:BP285) | BQ16: =SUM(BQ279:BQ285) | BR16: =SUM(BR279:BR285) | ... DF16: =SUM(DF279:DF285) | DH16: =SUM(DH279:DH285) | DI16: =SUM(DI279:DI285) | DJ16: =SUM(DJ279:DJ285) | DK16: =SUM(DK279:DK285) | DL16: =SUM(DL279:DL285) | DM16: =SUM(DM279:DM285) | DN16: =SUM(DN279:DN285) | DO16: =SUM(DO279:DO285) | ... FC16: =SUM(FC279:FC285) | FE16: =SUM(FE279:FE285) | FF16: =SUM(FF279:FF285) | FG16: =SUM(FG279:FG285) | FH16: =SUM(FH279:FH285) | FI16: =SUM(FI279:FI285) | FJ16: =SUM(FJ279:FJ285) | FK16: =SUM(FK279:FK285) | FL16: =SUM(FL279:FL285) | ... GZ16: =SUM(GZ279:GZ285)
A17: Pallas / Polaris | B17: 95.95 | D17: 164.99959 | E17: 79.978904 | N17: 0 | O17: 0 | P17: 0 | Q17: 0 | R17: 0 | S17: 0 | T17: 0 | U17: 0 | V17: 0 | W17: 0 | X17: 0 | Y17: 0 | Z17: 0 | AA17: 0 | AB17: 0 | AC17: 0 | AD17: 0 | AE17: 0 | AF17: 0 | AG17: 0 | AH17: 0 | AI17: 0 | AJ17: 0 | AK17: 0 | AL17: 0 | AM17: 0 | AN17: 0 | AO17: 0 | AP17: 0 | AQ17: 0 | AR17: 0 | AS17: 0 | AT17: 0 | AU17: 0 | AV17: 0 | AW17: 0 | AX17: 0 | AY17: 0 | AZ17: 0 | BA17: 0 | BB17: 0 | BC17: 0 | BD17: 0 | BE17: 0 | BF17: 0 | BG17: 0 | BH17: 0 | BI17: 0 | BK17: 0 | BL17: 0 | BM17: 0 | BN17: 0 | BO17: 0 | BP17: 0 | BQ17: 0 | BR17: 0 | BS17: 0 | BT17: 0 | BU17: 0 | BV17: 0 | BW17: 0 | BX17: 0 | BY17: 0 | BZ17: 0 | CA17: 0 | CB17: 0 | CC17: 0 | CD17: 0 | CE17: 0 | CF17: 0 | CG17: 0 | CH17: 0 | CI17: 0 | CJ17: 0 | CK17: 0 | CL17: 0 | CM17: 0 | CN17: 0 | CO17: 0 | CP17: 0 | CQ17: 0 | CR17: 0 | CS17: 0 | CT17: 0 | CU17: 0 | CV17: 0 | CW17: 0 | CX17: 0 | CY17: 0 | CZ17: 0 | DA17: 0 | DB17: 0 | DC17: 0 | DD17: 0 | DE17: 0 | DF17: 0 | DH17: 0 | DI17: 0 | DJ17: 0 | DK17: 0 | DL17: 0 | DM17: 0 | DN17: 0 | DO17: 0 | DP17: 0 | DQ17: 0 | DR17: 0 | DS17: 0 | DT17: 0 | DU17: 0 | DV17: 0 | DW17: 0 | DX17: 0 | DY17: 0 | DZ17: 0 | EA17: 0 | EB17: 0 | EC17: 0 | ED17: 0 | EE17: 0 | EF17: 0 | EG17: 0 | EH17: 0 | EI17: 0 | EJ17: 0 | EK17: 0 | EL17: 0 | EM17: 0 | EN17: 0 | EO17: 0 | EP17: 0 | EQ17: 0 | ER17: 0 | ES17: 0 | ET17: 0 | EU17: 0 | EV17: 0 | EW17: 0 | EX17: 0 | EY17: 0 | EZ17: 0 | FA17: 0 | FB17: 0 | FC17: 0 | FE17: 0 | FF17: 0 | FG17: 0 | FH17: 0 | FI17: 0 | FJ17: 0 | FK17: 0 | FL17: 0 | FM17: 0 | FN17: 0 | FO17: 0 | FP17: 0 | FQ17: 0 | FR17: 0 | FS17: 0 | FT17: 0 | FU17: 0 | FV17: 0 | FW17: 0 | FX17: 0 | FY17: 0 | FZ17: 0 | GA17: 0 | GB17: 0 | GC17: 0 | GD17: 0 | GE17: 0 | GF17: 0 | GG17: 0 | GH17: 0 | GI17: 0 | GJ17: 0 | GK17: 0 | GL17: 0 | GM17: 0 | GN17: 0 | GO17: 0 | GP17: 0 | GQ17: 0 | GR17: 0 | GS17: 0 | GT17: 0 | GU17: 0 | GV17: 0 | GW17: 0 | GX17: 0 | GY17: 0 | GZ17: 0
A18: Saturn / Orcus | B18: 95.87 | D18: 131.52127 | E18: 1.314988 | N18: 0 | O18: 0 | P18: 0 | Q18: 0 | R18: 0 | S18: 0 | T18: 0 | U18: 0 | V18: 0 | W18: 0 | X18: 0 | Y18: 0 | Z18: 0 | AA18: 0 | AB18: 0 | AC18: 0 | AD18: 0 | AE18: 0 | AF18: 0 | AG18: 0 | AH18: 0 | AI18: 0 | AJ18: 0 | AK18: 0 | AL18: 0 | AM18: 0 | AN18: 0 | AO18: 0 | AP18: 0 | AQ18: 0 | AR18: 0 | AS18: 0 | AT18: 0 | AU18: 0 | AV18: 0 | AW18: 0 | AX18: 0 | AY18: 0 | AZ18: 0 | BA18: 0 | BB18: 0 | BC18: 0 | BD18: 0 | BE18: 0 | BF18: 0 | BG18: 0 | BH18: 0 | BI18: 0 | BK18: 0 | BL18: 0 | BM18: 0 | BN18: 0 | BO18: 0 | BP18: 0 | BQ18: 0 | BR18: 0 | BS18: 0 | BT18: 0 | BU18: 0 | BV18: 0 | BW18: 0 | BX18: 0 | BY18: 0 | BZ18: 0 | CA18: 0 | CB18: 0 | CC18: 0 | CD18: 0 | CE18: 0 | CF18: 0 | CG18: 0 | CH18: 0 | CI18: 0 | CJ18: 0 | CK18: 0 | CL18: 0 | CM18: 0 | CN18: 0 | CO18: 0 | CP18: 0 | CQ18: 0 | CR18: 0 | CS18: 0 | CT18: 0 | CU18: 0 | CV18: 0 | CW18: 0 | CX18: 0 | CY18: 0 | CZ18: 0 | DA18: 0 | DB18: 0 | DC18: 0 | DD18: 0 | DE18: 0 | DF18: 0 | DH18: 0 | DI18: 0 | DJ18: 0 | DK18: 0 | DL18: 0 | DM18: 0 | DN18: 0 | DO18: 0 | DP18: 0 | DQ18: 0 | DR18: 0 | DS18: 0 | DT18: 0 | DU18: 0 | DV18: 0 | DW18: 0 | DX18: 0 | DY18: 0 | DZ18: 0 | EA18: 0 | EB18: 0 | EC18: 0 | ED18: 0 | EE18: 0 | EF18: 0 | EG18: 0 | EH18: 0 | EI18: 0 | EJ18: 0 | EK18: 0 | EL18: 0 | EM18: 0 | EN18: 0 | EO18: 0 | EP18: 0 | EQ18: 0 | ER18: 0 | ES18: 0 | ET18: 0 | EU18: 0 | EV18: 0 | EW18: 0 | EX18: 0 | EY18: 0 | EZ18: 0 | FA18: 0 | FB18: 0 | FC18: 0 | FE18: 0 | FF18: 0 | FG18: 0 | FH18: 0 | FI18: 0 | FJ18: 0 | FK18: 0 | FL18: 0 | FM18: 0 | FN18: 0 | FO18: 0 | FP18: 0 | FQ18: 0 | FR18: 0 | FS18: 0 | FT18: 0 | FU18: 0 | FV18: 0 | FW18: 0 | FX18: 0 | FY18: 0 | FZ18: 0 | GA18: 0 | GB18: 0 | GC18: 0 | GD18: 0 | GE18: 0 | GF18: 0 | GG18: 0 | GH18: 0 | GI18: 0 | GJ18: 0 | GK18: 0 | GL18: 0 | GM18: 0 | GN18: 0 | GO18: 0 | GP18: 0 | GQ18: 0 | GR18: 0 | GS18: 0 | GT18: 0 | GU18: 0 | GV18: 0 | GW18: 0 | GX18: 0 | GY18: 0 | GZ18: 0
A19: Juno / Arcturus | B19: 95.52 | D19: 161.82174 | E19: 21.521548 | N19: =SUM(N292:N304) | O19: =SUM(O292:O304) | P19: =SUM(P292:P304) | Q19: =SUM(Q292:Q304) | R19: =SUM(R292:R304) | S19: =SUM(S292:S304) | T19: =SUM(T292:T304) | U19: =SUM(U292:U304) | ... BI19: =SUM(BI292:BI304) | BK19: =SUM(BK292:BK304) | BL19: =SUM(BL292:BL304) | BM19: =SUM(BM292:BM304) | BN19: =SUM(BN292:BN304) | BO19: =SUM(BO292:BO304) | BP19: =SUM(BP292:BP304) | BQ19: =SUM(BQ292:BQ304) | BR19: =SUM(BR292:BR304) | ... DF19: =SUM(DF292:DF304) | DH19: =SUM(DH292:DH304) | DI19: =SUM(DI292:DI304) | DJ19: =SUM(DJ292:DJ304) | DK19: =SUM(DK292:DK304) | DL19: =SUM(DL292:DL304) | DM19: =SUM(DM292:DM304) | DN19: =SUM(DN292:DN304) | DO19: =SUM(DO292:DO304) | ... FC19: =SUM(FC292:FC304) | FE19: =SUM(FE292:FE304) | FF19: =SUM(FF292:FF304) | FG19: =SUM(FG292:FG304) | FH19: =SUM(FH292:FH304) | FI19: =SUM(FI292:FI304) | FJ19: =SUM(FJ292:FJ304) | FK19: =SUM(FK292:FK304) | FL19: =SUM(FL292:FL304) | ... GZ19: =SUM(GZ292:GZ304)
A20: Jupiter / Deneb Algedi | B20: 13.61 | C20: 95.51 | D20: 47.126954 | E20: 7.241544 | N20: =SUM(N306:N312) | O20: =SUM(O306:O312) | P20: =SUM(P306:P312) | Q20: =SUM(Q306:Q312) | R20: =SUM(R306:R312) | S20: =SUM(S306:S312) | T20: =SUM(T306:T312) | U20: =SUM(U306:U312) | ... BI20: =SUM(BI306:BI312) | BK20: =SUM(BK306:BK312) | BL20: =SUM(BL306:BL312) | BM20: =SUM(BM306:BM312) | BN20: =SUM(BN306:BN312) | BO20: =SUM(BO306:BO312) | BP20: =SUM(BP306:BP312) | BQ20: =SUM(BQ306:BQ312) | BR20: =SUM(BR306:BR312) | ... DF20: =SUM(DF306:DF312) | DH20: =SUM(DH306:DH312) | DI20: =SUM(DI306:DI312) | DJ20: =SUM(DJ306:DJ312) | DK20: =SUM(DK306:DK312) | DL20: =SUM(DL306:DL312) | DM20: =SUM(DM306:DM312) | DN20: =SUM(DN306:DN312) | DO20: =SUM(DO306:DO312) | ... FC20: =SUM(FC306:FC312) | FE20: =SUM(FE306:FE312) | FF20: =SUM(FF306:FF312) | FG20: =SUM(FG306:FG312) | FH20: =SUM(FH306:FH312) | FI20: =SUM(FI306:FI312) | FJ20: =SUM(FJ306:FJ312) | FK20: =SUM(FK306:FK312) | FL20: =SUM(FL306:FL312) | ... GZ20: =SUM(GZ306:GZ312)
A21: Venus / Vega | B21: 95.28 | D21: 133.29396 | E21: 25.223189 | N21: =SUM(N314:N320) | O21: =SUM(O314:O320) | P21: =SUM(P314:P320) | Q21: =SUM(Q314:Q320) | R21: =SUM(R314:R320) | S21: =SUM(S314:S320) | T21: =SUM(T314:T320) | U21: =SUM(U314:U320) | ... BI21: =SUM(BI314:BI320) | BK21: =SUM(BK314:BK320) | BL21: =SUM(BL314:BL320) | BM21: =SUM(BM314:BM320) | BN21: =SUM(BN314:BN320) | BO21: =SUM(BO314:BO320) | BP21: =SUM(BP314:BP320) | BQ21: =SUM(BQ314:BQ320) | BR21: =SUM(BR314:BR320) | ... DF21: =SUM(DF314:DF320) | DH21: =SUM(DH314:DH320) | DI21: =SUM(DI314:DI320) | DJ21: =SUM(DJ314:DJ320) | DK21: =SUM(DK314:DK320) | DL21: =SUM(DL314:DL320) | DM21: =SUM(DM314:DM320) | DN21: =SUM(DN314:DN320) | DO21: =SUM(DO314:DO320) | ... FC21: =SUM(FC314:FC320) | FE21: =SUM(FE314:FE320) | FF21: =SUM(FF314:FF320) | FG21: =SUM(FG314:FG320) | FH21: =SUM(FH314:FH320) | FI21: =SUM(FI314:FI320) | FJ21: =SUM(FJ314:FJ320) | FK21: =SUM(FK314:FK320) | FL21: =SUM(FL314:FL320) | ... GZ21: =SUM(GZ314:GZ320)
A22: Pallas / Spica | B22: 94.98 | D22: 31.999492 | E22: 20.44382 | N22: =SUM(N327:N330) | O22: =SUM(O327:O330) | P22: =SUM(P327:P330) | Q22: =SUM(Q327:Q330) | R22: =SUM(R327:R330) | S22: =SUM(S327:S330) | T22: =SUM(T327:T330) | U22: =SUM(U327:U330) | ... BI22: =SUM(BI327:BI330) | BK22: =SUM(BK327:BK330) | BL22: =SUM(BL327:BL330) | BM22: =SUM(BM327:BM330) | BN22: =SUM(BN327:BN330) | BO22: =SUM(BO327:BO330) | BP22: =SUM(BP327:BP330) | BQ22: =SUM(BQ327:BQ330) | BR22: =SUM(BR327:BR330) | ... DF22: =SUM(DF327:DF330) | DH22: =SUM(DH327:DH330) | DI22: =SUM(DI327:DI330) | DJ22: =SUM(DJ327:DJ330) | DK22: =SUM(DK327:DK330) | DL22: =SUM(DL327:DL330) | DM22: =SUM(DM327:DM330) | DN22: =SUM(DN327:DN330) | DO22: =SUM(DO327:DO330) | ... FC22: =SUM(FC327:FC330) | FE22: =SUM(FE327:FE330) | FF22: =SUM(FF327:FF330) | FG22: =SUM(FG327:FG330) | FH22: =SUM(FH327:FH330) | FI22: =SUM(FI327:FI330) | FJ22: =SUM(FJ327:FJ330) | FK22: =SUM(FK327:FK330) | FL22: =SUM(FL327:FL330) | ... GZ22: =SUM(GZ327:GZ330)
A23: Chiron / Castor | C23: 94.98 | D23: 82.734695 | E23: 40.000509 | N23: =SUM(N332:N341) | O23: =SUM(O332:O341) | P23: =SUM(P332:P341) | Q23: =SUM(Q332:Q341) | R23: =SUM(R332:R341) | S23: =SUM(S332:S341) | T23: =SUM(T332:T341) | U23: =SUM(U332:U341) | ... BI23: =SUM(BI332:BI341) | BK23: =SUM(BK332:BK341) | BL23: =SUM(BL332:BL341) | BM23: =SUM(BM332:BM341) | BN23: =SUM(BN332:BN341) | BO23: =SUM(BO332:BO341) | BP23: =SUM(BP332:BP341) | BQ23: =SUM(BQ332:BQ341) | BR23: =SUM(BR332:BR341) | ... DF23: =SUM(DF332:DF341) | DH23: =SUM(DH332:DH341) | DI23: =SUM(DI332:DI341) | DJ23: =SUM(DJ332:DJ341) | DK23: =SUM(DK332:DK341) | DL23: =SUM(DL332:DL341) | DM23: =SUM(DM332:DM341) | DN23: =SUM(DN332:DN341) | DO23: =SUM(DO332:DO341) | ... FC23: =SUM(FC332:FC341) | FE23: =SUM(FE332:FE341) | FF23: =SUM(FF332:FF341) | FG23: =SUM(FG332:FG341) | FH23: =SUM(FH332:FH341) | FI23: =SUM(FI332:FI341) | FJ23: =SUM(FJ332:FJ341) | FK23: =SUM(FK332:FK341) | FL23: =SUM(FL332:FL341) | ... GZ23: =SUM(GZ332:GZ341)
A24: Jupiter / Rigel | B24: 94.75 | D24: 158.99947 | E24: 15.16869 | N24: =SUM(N343:N361) | O24: =SUM(O343:O361) | P24: =SUM(P343:P361) | Q24: =SUM(Q343:Q361) | R24: =SUM(R343:R361) | S24: =SUM(S343:S361) | T24: =SUM(T343:T361) | U24: =SUM(U343:U361) | ... BI24: =SUM(BI343:BI361) | BK24: =SUM(BK343:BK361) | BL24: =SUM(BL343:BL361) | BM24: =SUM(BM343:BM361) | BN24: =SUM(BN343:BN361) | BO24: =SUM(BO343:BO361) | BP24: =SUM(BP343:BP361) | BQ24: =SUM(BQ343:BQ361) | BR24: =SUM(BR343:BR361) | ... DF24: =SUM(DF343:DF361) | DH24: =SUM(DH343:DH361) | DI24: =SUM(DI343:DI361) | DJ24: =SUM(DJ343:DJ361) | DK24: =SUM(DK343:DK361) | DL24: =SUM(DL343:DL361) | DM24: =SUM(DM343:DM361) | DN24: =SUM(DN343:DN361) | DO24: =SUM(DO343:DO361) | ... FC24: =SUM(FC343:FC361) | FE24: =SUM(FE343:FE361) | FF24: =SUM(FF343:FF361) | FG24: =SUM(FG343:FG361) | FH24: =SUM(FH343:FH361) | FI24: =SUM(FI343:FI361) | FJ24: =SUM(FJ343:FJ361) | FK24: =SUM(FK343:FK361) | FL24: =SUM(FL343:FL361) | ... GZ24: =SUM(GZ343:GZ361)
A25: Sedna / Alkaid | B25: 12.79 | C25: 94.65 | D25: 161.28371 | E25: 44.449493 | N25: =SUM(N363:N383) | O25: =SUM(O363:O383) | P25: =SUM(P363:P383) | Q25: =SUM(Q363:Q383) | R25: =SUM(R363:R383) | S25: =SUM(S363:S383) | T25: =SUM(T363:T383) | U25: =SUM(U363:U383) | ... BI25: =SUM(BI363:BI383) | BK25: =SUM(BK363:BK383) | BL25: =SUM(BL363:BL383) | BM25: =SUM(BM363:BM383) | BN25: =SUM(BN363:BN383) | BO25: =SUM(BO363:BO383) | BP25: =SUM(BP363:BP383) | BQ25: =SUM(BQ363:BQ383) | BR25: =SUM(BR363:BR383) | ... DF25: =SUM(DF363:DF383) | DH25: =SUM(DH363:DH383) | DI25: =SUM(DI363:DI383) | DJ25: =SUM(DJ363:DJ383) | DK25: =SUM(DK363:DK383) | DL25: =SUM(DL363:DL383) | DM25: =SUM(DM363:DM383) | DN25: =SUM(DN363:DN383) | DO25: =SUM(DO363:DO383) | ... FC25: =SUM(FC363:FC383) | FE25: =SUM(FE363:FE383) | FF25: =SUM(FF363:FF383) | FG25: =SUM(FG363:FG383) | FH25: =SUM(FH363:FH383) | FI25: =SUM(FI363:FI383) | FJ25: =SUM(FJ363:FJ383) | FK25: =SUM(FK363:FK383) | FL25: =SUM(FL363:FL383) | ... GZ25: =SUM(GZ363:GZ383)
A26: Sun / Antares | B26: 1.33 | C26: 94.22 | D26: 62.076723 | E26: 24.145677 | N26: =SUM(N390:N396) | O26: =SUM(O390:O396) | P26: =SUM(P390:P396) | Q26: =SUM(Q390:Q396) | R26: =SUM(R390:R396) | S26: =SUM(S390:S396) | T26: =SUM(T390:T396) | U26: =SUM(U390:U396) | ... BI26: =SUM(BI390:BI396) | BK26: =SUM(BK390:BK396) | BL26: =SUM(BL390:BL396) | BM26: =SUM(BM390:BM396) | BN26: =SUM(BN390:BN396) | BO26: =SUM(BO390:BO396) | BP26: =SUM(BP390:BP396) | BQ26: =SUM(BQ390:BQ396) | BR26: =SUM(BR390:BR396) | ... DF26: =SUM(DF390:DF396) | DH26: =SUM(DH390:DH396) | DI26: =SUM(DI390:DI396) | DJ26: =SUM(DJ390:DJ396) | DK26: =SUM(DK390:DK396) | DL26: =SUM(DL390:DL396) | DM26: =SUM(DM390:DM396) | DN26: =SUM(DN390:DN396) | DO26: =SUM(DO390:DO396) | ... FC26: =SUM(FC390:FC396) | FE26: =SUM(FE390:FE396) | FF26: =SUM(FF390:FF396) | FG26: =SUM(FG390:FG396) | FH26: =SUM(FH390:FH396) | FI26: =SUM(FI390:FI396) | FJ26: =SUM(FJ390:FJ396) | FK26: =SUM(FK390:FK396) | FL26: =SUM(FL390:FL396) | ... GZ26: =SUM(GZ390:GZ396)
A27: Pallas / Betelgeuse | B27: 94.21 | C27: 10.18 | D27: 144.49913 | E27: 1.876413 | N27: =SUM(N398:N405) | O27: =SUM(O398:O405) | P27: =SUM(P398:P405) | Q27: =SUM(Q398:Q405) | R27: =SUM(R398:R405) | S27: =SUM(S398:S405) | T27: =SUM(T398:T405) | U27: =SUM(U398:U405) | ... BI27: =SUM(BI398:BI405) | BK27: =SUM(BK398:BK405) | BL27: =SUM(BL398:BL405) | BM27: =SUM(BM398:BM405) | BN27: =SUM(BN398:BN405) | BO27: =SUM(BO398:BO405) | BP27: =SUM(BP398:BP405) | BQ27: =SUM(BQ398:BQ405) | BR27: =SUM(BR398:BR405) | ... DF27: =SUM(DF398:DF405) | DH27: =SUM(DH398:DH405) | DI27: =SUM(DI398:DI405) | DJ27: =SUM(DJ398:DJ405) | DK27: =SUM(DK398:DK405) | DL27: =SUM(DL398:DL405) | DM27: =SUM(DM398:DM405) | DN27: =SUM(DN398:DN405) | DO27: =SUM(DO398:DO405) | ... FC27: =SUM(FC398:FC405) | FE27: =SUM(FE398:FE405) | FF27: =SUM(FF398:FF405) | FG27: =SUM(FG398:FG405) | FH27: =SUM(FH398:FH405) | FI27: =SUM(FI398:FI405) | FJ27: =SUM(FJ398:FJ405) | FK27: =SUM(FK398:FK405) | FL27: =SUM(FL398:FL405) | ... GZ27: =SUM(GZ398:GZ405)
A28: Neptune / Bellatrix | B28: 94.21 | D28: 144.38975 | E28: 27.024514 | N28: =SUM(N407:N417) | O28: =SUM(O407:O417) | P28: =SUM(P407:P417) | Q28: =SUM(Q407:Q417) | R28: =SUM(R407:R417) | S28: =SUM(S407:S417) | T28: =SUM(T407:T417) | U28: =SUM(U407:U417) | ... BI28: =SUM(BI407:BI417) | BK28: =SUM(BK407:BK417) | BL28: =SUM(BL407:BL417) | BM28: =SUM(BM407:BM417) | BN28: =SUM(BN407:BN417) | BO28: =SUM(BO407:BO417) | BP28: =SUM(BP407:BP417) | BQ28: =SUM(BQ407:BQ417) | BR28: =SUM(BR407:BR417) | ... DF28: =SUM(DF407:DF417) | DH28: =SUM(DH407:DH417) | DI28: =SUM(DI407:DI417) | DJ28: =SUM(DJ407:DJ417) | DK28: =SUM(DK407:DK417) | DL28: =SUM(DL407:DL417) | DM28: =SUM(DM407:DM417) | DN28: =SUM(DN407:DN417) | DO28: =SUM(DO407:DO417) | ... FC28: =SUM(FC407:FC417) | FE28: =SUM(FE407:FE417) | FF28: =SUM(FF407:FF417) | FG28: =SUM(FG407:FG417) | FH28: =SUM(FH407:FH417) | FI28: =SUM(FI407:FI417) | FJ28: =SUM(FJ407:FJ417) | FK28: =SUM(FK407:FK417) | FL28: =SUM(FL407:FL417) | ... GZ28: =SUM(GZ407:GZ417)
A29: Vesta / Procyon | B29: 43.68 | C29: 93.96 | D29: 133.80264 | E29: 26.176325 | N29: =SUM(N419:N425) | O29: =SUM(O419:O425) | P29: =SUM(P419:P425) | Q29: =SUM(Q419:Q425) | R29: =SUM(R419:R425) | S29: =SUM(S419:S425) | T29: =SUM(T419:T425) | U29: =SUM(U419:U425) | ... BI29: =SUM(BI419:BI425) | BK29: =SUM(BK419:BK425) | BL29: =SUM(BL419:BL425) | BM29: =SUM(BM419:BM425) | BN29: =SUM(BN419:BN425) | BO29: =SUM(BO419:BO425) | BP29: =SUM(BP419:BP425) | BQ29: =SUM(BQ419:BQ425) | BR29: =SUM(BR419:BR425) | ... DF29: =SUM(DF419:DF425) | DH29: =SUM(DH419:DH425) | DI29: =SUM(DI419:DI425) | DJ29: =SUM(DJ419:DJ425) | DK29: =SUM(DK419:DK425) | DL29: =SUM(DL419:DL425) | DM29: =SUM(DM419:DM425) | DN29: =SUM(DN419:DN425) | DO29: =SUM(DO419:DO425) | ... FC29: =SUM(FC419:FC425) | FE29: =SUM(FE419:FE425) | FF29: =SUM(FF419:FF425) | FG29: =SUM(FG419:FG425) | FH29: =SUM(FH419:FH425) | FI29: =SUM(FI419:FI425) | FJ29: =SUM(FJ419:FJ425) | FK29: =SUM(FK419:FK425) | FL29: =SUM(FL419:FL425) | ... GZ29: =SUM(GZ419:GZ425)
